Workbook

Sheet flows
D1: EU | E1: EU | F1: EU | G1: EU | H1: EU | I1: EU | J1: EU | K1: EU | L1: EU | M1: EU | N1: EU | O1: EU | P1: EU | Q1: EU | R1: EU | S1: EU | T1: EU | U1: EU | V1: EU | W1: EU | X1: EU | Y1: EU | Z1: EU | AA1: EU | AB1: EU | AC1: EU | AD1: EU | AE1: EU | AF1: EU | AG1: EU | AH1: EU | AI1: EU | AJ1: EU | AK1: EU | AL1: EU | AM1: EU | AN1: EU | AO1: EU | AP1: EU | AQ1: EU | AR1: EU | AS1: EU | AT1: EU | AU1: EU | AV1: EU | AW1: EU | AX1: EU | AY1: EU | AZ1: EU | BA1: EU | BB1: EU | BC1: EU | BD1: EU | BE1: EU | BF1: RoW | BG1: RoW | BH1: RoW | BI1: RoW | BJ1: RoW | BK1: RoW | BL1: RoW | BM1: RoW | BN1: RoW | BO1: RoW | BP1: RoW | BQ1: RoW | BR1: RoW | BS1: RoW | BT1: RoW | BU1: RoW | BV1: RoW | BW1: RoW | BX1: RoW | BY1: RoW | BZ1: RoW | CA1: RoW | CB1: RoW | CC1: RoW | CD1: RoW | CE1: RoW | CF1: RoW | CG1: RoW | CH1: RoW | CI1: RoW | CJ1: RoW | CK1: RoW | CL1: RoW | CM1: RoW | CN1: RoW | CO1: RoW | CP1: RoW | CQ1: RoW | CR1: RoW | CS1: RoW | CT1: RoW | CU1: RoW | CV1: RoW | CW1: RoW | CX1: RoW | CY1: RoW | CZ1: RoW | DA1: RoW | DB1: RoW | DC1: RoW | DD1: RoW | DE1: RoW | DF1: RoW | DG1: RoW | DH1: EU | DI1: EU | DJ1: EU | DK1: EU | DL1: RoW | DM1: RoW | DN1: RoW | DO1: RoW
D2: Sector | E2: Sector | F2: Sector | G2: Sector | H2: Sector | I2: Sector | J2: Sector | K2: Sector | L2: Sector | M2: Sector | N2: Sector | O2: Sector | P2: Sector | Q2: Sector | R2: Sector | S2: Sector | T2: Sector | U2: Sector | V2: Sector | W2: Sector | X2: Sector | Y2: Sector | Z2: Sector | AA2: Sector | AB2: Sector | AC2: Sector | AD2: Sector | AE2: Sector | AF2: Sector | AG2: Sector | AH2: Sector | AI2: Sector | AJ2: Sector | AK2: Sector | AL2: Sector | AM2: Sector | AN2: Sector | AO2: Sector | AP2: Sector | AQ2: Sector | AR2: Sector | AS2: Sector | AT2: Sector | AU2: Sector | AV2: Sector | AW2: Sector | AX2: Sector | AY2: Sector | AZ2: Sector | BA2: Sector | BB2: Sector | BC2: Sector | BD2: Sector | BE2: Sector | BF2: Sector | BG2: Sector | BH2: Sector | BI2: Sector | BJ2: Sector | BK2: Sector | BL2: Sector | BM2: Sector | BN2: Sector | BO2: Sector | BP2: Sector | BQ2: Sector | BR2: Sector | BS2: Sector | BT2: Sector | BU2: Sector | BV2: Sector | BW2: Sector | BX2: Sector | BY2: Sector | BZ2: Sector | CA2: Sector | CB2: Sector | CC2: Sector | CD2: Sector | CE2: Sector | CF2: Sector | CG2: Sector | CH2: Sector | CI2: Sector | CJ2: Sector | CK2: Sector | CL2: Sector | CM2: Sector | CN2: Sector | CO2: Sector | CP2: Sector | CQ2: Sector | CR2: Sector | CS2: Sector | CT2: Sector | CU2: Sector | CV2: Sector | CW2: Sector | CX2: Sector | CY2: Sector | CZ2: Sector | DA2: Sector | DB2: Sector | DC2: Sector | DD2: Sector | DE2: Sector | DF2: Sector | DG2: Sector | DH2: Consumption category | DI2: Consumption category | DJ2: Consumption category | DK2: Consumption category | DL2: Consumption category | DM2: Consumption category | DN2: Consumption category | DO2: Consumption category
D3: Agriculture | E3: Animal Farming | F3: Forestry, logging and related service activities (02) | G3: Fishing, operating of fish hatcheries and fish farms; service activities incidental to fishing (05) | H3: Extraction of Fossil-Fuels | I3: Mining & Quarrying of raw materials | J3: Processing of meat | K3: Processing of other food&beverage | L3: Manufacture of tobacco products (16) | M3: Manufacture of textiles | N3: Manufacture of wood and of products of wood and cork, except furniture; manufacture of articles of straw and plaiting materials (20) | O3: Re-processing of secondary wood material into new wood material | P3: Pulp | Q3: Re-processing of secondary paper into new pulp | R3: Paper | S3: Processing of Fossil Fuels | T3: Plastics, basic | U3: Re-processing of secondary plastic into new plastic | V3: Manufacture of Chemicals | W3: Manufacture of rubber and plastic products (25) | X3: Manufacture of glass and glass products | Y3: Re-processing of secondary glass into new glass | Z3: Manufacture of other non-metallic mineral products | AA3: Manufacture of cement, lime and plaster | AB3: Re-processing of ash into clinker | AC3: Manufacture of Metals | AD3: Re-processing of Metals | AE3: Manufacture of durable goods | AF3: Manufacture of furniture; manufacturing n.e.c. (36) | AG3: Recycling | AH3: Production of electricity by fossil fuels | AI3: Production of electricity by renewable energy | AJ3: Transmission & Distribution | AK3: Manufacture of gas; distribution of gaseous fuels through mains | AL3: Water | AM3: Construction (45) | AN3: Re-processing of secondary construction material into aggregates | AO3: Sale, maintenance, repair of motor vehicles, motor vehicles parts, motorcycles, motor cycles parts and accessoiries | AP3: Retail sale of automotive fuel | AQ3: Retail & Wholesale trade | AR3: Leisure Services | AS3: Transport | AT3: KIBS | AU3: Real estate activities (70) | AV3: Renting of machinery and equipment without operator and of personal and household goods (71) | AW3: Research and development (73) | AX3: Public administration and defence; compulsory social security (75) | AY3: Education (80) | AZ3: Health and social work (85) | BA3: Incineration of Waste | BB3: Biogas & Composting | BC3: Waste water | BD3: Landfill of Waste | BE3: Other Services | BF3: Agriculture | BG3: Animal Farming | BH3: Forestry, logging and related service activities (02) | BI3: Fishing, operating of fish hatcheries and fish farms; service activities incidental to fishing (05) | BJ3: Extraction of Fossil-Fuels | BK3: Mining & Quarrying of raw materials | BL3: Processing of meat | BM3: Processing of other food&beverage | BN3: Manufacture of tobacco products (16) | BO3: Manufacture of textiles | BP3: Manufacture of wood and of products of wood and cork, except furniture; manufacture of articles of straw and plaiting materials (20) | BQ3: Re-processing of secondary wood material into new wood material | BR3: Pulp | BS3: Re-processing of secondary paper into new pulp | BT3: Paper | BU3: Processing of Fossil Fuels | BV3: Plastics, basic | BW3: Re-processing of secondary plastic into new plastic | BX3: Manufacture of Chemicals | BY3: Manufacture of rubber and plastic products (25) | BZ3: Manufacture of glass and glass products | CA3: Re-processing of secondary glass into new glass | CB3: Manufacture of other non-metallic mineral products | CC3: Manufacture of cement, lime and plaster | CD3: Re-processing of ash into clinker | CE3: Manufacture of Metals | CF3: Re-processing of Metals | CG3: Manufacture of durable goods | CH3: Manufacture of furniture; manufacturing n.e.c. (36) | CI3: Recycling | CJ3: Production of electricity by fossil fuels | CK3: Production of electricity by renewable energy | CL3: Transmission & Distribution | CM3: Manufacture of gas; distribution of gaseous fuels through mains | CN3: Water | CO3: Construction (45) | CP3: Re-processing of secondary construction material into aggregates | CQ3: Sale, maintenance, repair of motor vehicles, motor vehicles parts, motorcycles, motor cycles parts and accessoiries | CR3: Retail sale of automotive fuel | CS3: Retail & Wholesale trade | CT3: Leisure Services | CU3: Transport | CV3: KIBS | CW3: Real estate activities (70) | CX3: Renting of machinery and equipment without operator and of personal and household goods (71) | CY3: Research and development (73) | CZ3: Public administration and defence; compulsory social security (75) | DA3: Education (80) | DB3: Health and social work (85) | DC3: Incineration of Waste | DD3: Biogas & Composting | DE3: Waste water | DF3: Landfill of Waste | DG3: Other Services | DH3: Consumption | DI3: Final consumption expenditure by government | DJ3: GFCF | DK3: Exports: Total (fob) | DL3: Consumption | DM3: Final consumption expenditure by government | DN3: GFCF | DO3: Exports: Total (fob) | DQ3: Final Demand | DR3: Sector Share in Total Final Demand
A4: EU | B4: Sector | C4: Agriculture | D4: 8803.6991 | E4: 16240.262 | F4: 360.83742 | G4: 25.311202 | H4: 13.129934 | I4: 20.441096 | J4: 11248.607 | K4: 50197.749 | L4: 555.0464 | M4: 573.00978 | N4: 44.470807 | O4: 18.993006 | P4: 7.5353694 | Q4: 13.55555 | R4: 71.622524 | S4: 82.84664 | T4: 579.01984 | U4: 183.68161 | V4: 324.90242 | W4: 42.13407 | X4: 1.3361302 | Y4: 0.57214146 | Z4: 11.433018 | AA4: 7.4762978 | AB4: 1.9506785 | AC4: 20.132222 | AD4: 11.58373 | AE4: 234.37868 | AF4: 24.056063 | AG4: 4.7169939 | AH4: 21.157032 | AI4: 48.754638 | AJ4: 22.960809 | AK4: 10.871347 | AL4: 18.598645 | AM4: 357.71997 | AN4: 1.0825321 | AO4: 14.082722 | AP4: 9.7755484 | AQ4: 1292.4246 | AR4: 6765.0953 | AS4: 286.9124 | AT4: 1531.1713 | AU4: 108.42601 | AV4: 69.029443 | AW4: 73.580716 | AX4: 1057.9237 | AY4: 294.98862 | AZ4: 1413.7604 | BA4: 41.957275 | BB4: 6.9276913 | BC4: 7.6941768 | BD4: 14.983323 | BE4: 178.78636 | BF4: 965.2175 | BG4: 692.84923 | BH4: 88.03311 | BI4: 10.027684 | BJ4: 106.29395 | BK4: 56.264184 | BL4: 333.59113 | BM4: 2368.4797 | BN4: 527.08792 | BO4: 533.44196 | BP4: 42.839671 | BQ4: 0.44490747 | BR4: 9.971673 | BS4: 0.47262363 | BT4: 53.828867 | BU4: 78.205172 | BV4: 6.4553879 | BW4: 0.59234732 | BX4: 2381.9896 | BY4: 2.7466132 | BZ4: 5.393543 | CA4: 0.029553505 | CB4: 11.139308 | CC4: 5.3166818 | CD4: 0.045894036 | CE4: 213.84242 | CF4: 0.54887531 | CG4: 114.69785 | CH4: 16.129967 | CI4: 9.9723009 | CJ4: 124.28609 | CK4: 27.794842 | CL4: 74.950895 | CM4: 123.40404 | CN4: 2.9415742 | CO4: 223.32075 | CP4: 0.00054050234 | CQ4: 40.514858 | CR4: 28.301149 | CS4: 131.90605 | CT4: 868.60511 | CU4: 126.0903 | CV4: 581.15382 | CW4: 366.62994 | CX4: 165.65554 | CY4: 43.541988 | CZ4: 93.481002 | DA4: 232.95168 | DB4: 396.15983 | DC4: 0.16436782 | DD4: 0.070122378 | DE4: 0.52296247 | DF4: 96.476838 | DG4: 233.29362 | DH4: 86708.162 | DI4: 772.08459 | DJ4: 4035.6257 | DK4: 0 | DL4: 11170.928 | DM4: 3.9765862 | DN4: 205.64305 | DO4: 0 | DQ4: =SUM(DL4:DN4) -> 11380.548 | DR4: =DQ4/SUM(DQ$4:DQ$57) -> 0.011073165
A5: EU | B5: Sector | C5: Animal Farming | D5: 21.516292 | E5: 1410.103 | F5: 6.295688 | G5: 2.3099831 | H5: 12.90772 | I5: 6.5145027 | J5: 83314.272 | K5: 29544.863 | L5: 40.421047 | M5: 372.19566 | N5: 13.283675 | O5: 3.6478333 | P5: 1.624197 | Q5: 4.4196655 | R5: 28.307719 | S5: 17.801515 | T5: 35.081518 | U5: 14.23652 | V5: 15.886971 | W5: 13.143119 | X5: 0.76574425 | Y5: 0.32176234 | Z5: 4.6070878 | AA5: 6.0913636 | AB5: 1.3559557 | AC5: 16.440439 | AD5: 5.2847002 | AE5: 187.69476 | AF5: 14.384862 | AG5: 2.387502 | AH5: 23.283812 | AI5: 4.4548176 | AJ5: 42.583807 | AK5: 10.999867 | AL5: 5.6027332 | AM5: 100.26945 | AN5: 1.4128073 | AO5: 9.9079229 | AP5: 5.308718 | AQ5: 744.27893 | AR5: 1461.0087 | AS5: 185.26292 | AT5: 552.76062 | AU5: 46.716625 | AV5: 59.407725 | AW5: 25.547914 | AX5: 221.33746 | AY5: 74.157706 | AZ5: 277.63048 | BA5: 41.253359 | BB5: 5.8148076 | BC5: 3.1439891 | BD5: 4.3001306 | BE5: 168.24091 | BF5: 31.060319 | BG5: 49.230982 | BH5: 1.0458534 | BI5: 0.95107341 | BJ5: 19.86017 | BK5: 18.008154 | BL5: 156.27782 | BM5: 138.60114 | BN5: 0.30296561 | BO5: 90.725894 | BP5: 1.310645 | BQ5: 0.44996364 | BR5: 0.18598812 | BS5: 0.10919755 | BT5: 2.7263039 | BU5: 238.68922 | BV5: 0.78615175 | BW5: 0.092025501 | BX5: 391.66317 | BY5: 8.27457 | BZ5: 0.63210044 | CA5: 0.012600311 | CB5: 0.72790853 | CC5: 0.43123645 | CD5: 0.019888476 | CE5: 109.19383 | CF5: 0.15386147 | CG5: 19.741343 | CH5: 11.012061 | CI5: 1.0565367 | CJ5: 0.96438033 | CK5: 1.6354781 | CL5: 0.37273646 | CM5: 5.7113697 | CN5: 0.13815267 | CO5: 13.273804 | CP5: 0.00050490223 | CQ5: 2.7435637 | CR5: 0.21960793 | CS5: 13.191303 | CT5: 105.08456 | CU5: 9.4502403 | CV5: 44.405097 | CW5: 32.239863 | CX5: 21.393939 | CY5: 8.2711632 | CZ5: 14.801017 | DA5: 54.790409 | DB5: 50.865629 | DC5: 0.1751225 | DD5: 0.096714204 | DE5: 0.61516198 | DF5: 0.65271707 | DG5: 48.677188 | DH5: 31069.75 | DI5: 338.35783 | DJ5: 10212.043 | DK5: 0 | DL5: 740.59621 | DM5: 34.270392 | DN5: 640.05016 | DO5: 0 | DQ5: =SUM(DL5:DN5) -> 1414.9168 | DR5: =DQ5/SUM(DQ$4:DQ$57) -> 0.0013767005
A6: EU | B6: Sector | C6: Forestry, logging and related service activities (02) | D6: 89.57997 | E6: 289.71842 | F6: 8819.7701 | G6: 4.4464753 | H6: 55.948028 | I6: 46.959943 | J6: 69.119391 | K6: 322.69468 | L6: 55.499172 | M6: 73.983448 | N6: 11774.783 | O6: 88.823391 | P6: 763.57891 | Q6: 8.6042431 | R6: 2224.1065 | S6: 6.3571942 | T6: 45.363287 | U6: 14.832391 | V6: 45.929935 | W6: 100.48155 | X6: 6.914999 | Y6: 1.4944305 | Z6: 18.815196 | AA6: 15.412492 | AB6: 3.0757718 | AC6: 21.838022 | AD6: 6.76502 | AE6: 146.81855 | AF6: 464.44293 | AG6: 6.0429745 | AH6: 15.852174 | AI6: 162.63867 | AJ6: 15.66696 | AK6: 4.3639313 | AL6: 14.566218 | AM6: 1014.2768 | AN6: 0.032996608 | AO6: 10.195033 | AP6: 1.755637 | AQ6: 121.23766 | AR6: 126.6466 | AS6: 70.861333 | AT6: 185.78118 | AU6: 65.027106 | AV6: 3.2025325 | AW6: 7.1310122 | AX6: 138.38523 | AY6: 23.869501 | AZ6: 30.322802 | BA6: 4.6411499 | BB6: 1.3993722 | BC6: 1.2102875 | BD6: 2.8859218 | BE6: 39.116463 | BF6: 8.8127152 | BG6: 13.729107 | BH6: 72.13864 | BI6: 0.24548987 | BJ6: 12.133331 | BK6: 1.0724971 | BL6: 1.2658671 | BM6: 27.35311 | BN6: 9.9496398 | BO6: 19.413531 | BP6: 245.01455 | BQ6: 3.5332062 | BR6: 7.8631387 | BS6: 0.022884189 | BT6: 139.46367 | BU6: 1.0020514 | BV6: 0.70259084 | BW6: 0.073392036 | BX6: 168.58203 | BY6: 72.857993 | BZ6: 0.41698603 | CA6: 0.02283068 | CB6: 0.80617596 | CC6: 0.30200749 | CD6: 0.010531091 | CE6: 9.2425871 | CF6: 0.023435224 | CG6: 8.7100393 | CH6: 38.867712 | CI6: 0.75641906 | CJ6: 0.17030768 | CK6: 0.17687698 | CL6: 0.17643505 | CM6: 0.3416055 | CN6: 0.069872123 | CO6: 111.76247 | CP6: 4.7273205e-05 | CQ6: 0.60852597 | CR6: 0.12300299 | CS6: 7.3869222 | CT6: 10.577153 | CU6: 16.246134 | CV6: 6.4365494 | CW6: 8.7620665 | CX6: 1.3839587 | CY6: 3.5946734 | CZ6: 5.3642951 | DA6: 2.8306211 | DB6: 5.6786091 | DC6: 0.13131392 | DD6: 0.030640128 | DE6: 0.055511251 | DF6: 0.12407026 | DG6: 1.6140561 | DH6: 6546.6653 | DI6: 345.76523 | DJ6: 4631.7332 | DK6: 0 | DL6: 321.66744 | DM6: 3.4734653 | DN6: 35.834991 | DO6: 0 | DQ6: =SUM(DL6:DN6) -> 360.97589 | DR6: =DQ6/SUM(DQ$4:DQ$57) -> 0.0003512261
A7: EU | B7: Sector | C7: Fishing, operating of fish hatcheries and fish farms; service activities incidental to fishing (05) | D7: 1.1935058 | E7: 63.336381 | F7: 15.462937 | G7: 442.40274 | H7: 0.29474942 | I7: 0.30574242 | J7: 797.08059 | K7: 1138.6526 | L7: 18.180075 | M7: 21.601083 | N7: 1.6828152 | O7: 0.13382889 | P7: 0.20092095 | Q7: 0.23202509 | R7: 2.8277997 | S7: 1.0512411 | T7: 52.967871 | U7: 14.872061 | V7: 6.1699391 | W7: 14.705098 | X7: 0.18983727 | Y7: 0.08398566 | Z7: 0.27910818 | AA7: 0.38975227 | AB7: 0.11129984 | AC7: 0.49649432 | AD7: 0.45480829 | AE7: 8.5136366 | AF7: 0.80390806 | AG7: 0.65062055 | AH7: 9.1552696 | AI7: 3.7910555 | AJ7: 4.6680886 | AK7: 7.0737141 | AL7: 9.0143175 | AM7: 4.4252201 | AN7: 87.853237 | AO7: 4.3095728 | AP7: 3.3220867 | AQ7: 22.504829 | AR7: 1016.797 | AS7: 77.89723 | AT7: 32.302143 | AU7: 3.2530291 | AV7: 0.95595871 | AW7: 2.1014594 | AX7: 33.725472 | AY7: 19.768622 | AZ7: 88.115206 | BA7: 1.4518367 | BB7: 0.30347838 | BC7: 0.26327414 | BD7: 1.2605387 | BE7: 20.444427 | BF7: 0.61787243 | BG7: 1.4115068 | BH7: 0.04847588 | BI7: 66.132301 | BJ7: 0.40886281 | BK7: 0.38943538 | BL7: 285.17185 | BM7: 69.569587 | BN7: 0.056899713 | BO7: 0.93919915 | BP7: 0.09018245 | BQ7: 0.018658586 | BR7: 0.027870126 | BS7: 0.012619982 | BT7: 0.23746988 | BU7: 1.5193682 | BV7: 0.13697376 | BW7: 0.0063188725 | BX7: 69.205375 | BY7: 0.1392341 | BZ7: 0.045556426 | CA7: 0.00088111356 | CB7: 0.12170564 | CC7: 0.059537975 | CD7: 0.0016212622 | CE7: 0.37536731 | CF7: 0.016546925 | CG7: 2.1513659 | CH7: 0.18643101 | CI7: 0.072237582 | CJ7: 0.1785108 | CK7: 0.038196783 | CL7: 0.089403264 | CM7: 0.087307882 | CN7: 0.025804673 | CO7: 1.8521021 | CP7: 4.4060931e-05 | CQ7: 0.16384997 | CR7: 0.31206286 | CS7: 2.2777897 | CT7: 38.935992 | CU7: 9.0904408 | CV7: 4.465411 | CW7: 0.79988689 | CX7: 0.2500641 | CY7: 0.5621106 | CZ7: 4.8381069 | DA7: 3.2393843 | DB7: 19.526558 | DC7: 0.015642556 | DD7: 0.0058069869 | DE7: 0.023898679 | DF7: 0.096913235 | DG7: 3.5577435 | DH7: 9300.7622 | DI7: 6.6649199 | DJ7: 95.659851 | DK7: 0 | DL7: 450.69839 | DM7: 0.12423353 | DN7: 3.8911598 | DO7: 0 | DQ7: =SUM(DL7:DN7) -> 454.71378 | DR7: =DQ7/SUM(DQ$4:DQ$57) -> 0.00044243217
A8: EU | B8: Sector | C8: Extraction of Fossil-Fuels | D8: 213.56477 | E8: 153.0602 | F8: 20.540615 | G8: 3.4629964 | H8: 1841.0068 | I8: 165.22296 | J8: 177.50445 | K8: 248.82059 | L8: 16.261391 | M8: 567.34811 | N8: 286.26005 | O8: 61.344885 | P8: 98.861554 | Q8: 54.020036 | R8: 98.180084 | S8: 11867.415 | T8: 575.02026 | U8: 41.13826 | V8: 763.14349 | W8: 136.53935 | X8: 52.88625 | Y8: 45.03402 | Z8: 216.83546 | AA8: 312.92884 | AB8: 64.425131 | AC8: 1948.7127 | AD8: 278.98938 | AE8: 603.58281 | AF8: 308.16191 | AG8: 29.347179 | AH8: 15270.787 | AI8: 65.661219 | AJ8: 302.83693 | AK8: 2545.0497 | AL8: 1793.2118 | AM8: 510.88466 | AN8: 0.14582771 | AO8: 40.778683 | AP8: 26.772952 | AQ8: 281.26441 | AR8: 162.74962 | AS8: 490.06228 | AT8: 698.80377 | AU8: 249.22008 | AV8: 44.928811 | AW8: 69.491978 | AX8: 439.17428 | AY8: 97.252992 | AZ8: 143.21472 | BA8: 24.864159 | BB8: 10.276423 | BC8: 8.03165 | BD8: 14.143652 | BE8: 254.9043 | BF8: 17.043234 | BG8: 6.5733322 | BH8: 0.90046739 | BI8: 0.86606329 | BJ8: 196.92474 | BK8: 21.163117 | BL8: 10.56754 | BM8: 14.606403 | BN8: 0.62027478 | BO8: 22.375288 | BP8: 512.26574 | BQ8: 0.7572404 | BR8: 8.967718 | BS8: 0.22659783 | BT8: 8.1064575 | BU8: 1776.7115 | BV8: 44.077106 | BW8: 0.18674364 | BX8: 136.33049 | BY8: 8.995227 | BZ8: 6.018248 | CA8: 0.51030165 | CB8: 15.93318 | CC8: 21.11591 | CD8: 0.94162236 | CE8: 62.210594 | CF8: 1.552043 | CG8: 47.905854 | CH8: 401.62386 | CI8: 0.46554732 | CJ8: 554.54075 | CK8: 7.4413355 | CL8: 6.0553599 | CM8: 319.05987 | CN8: 17.080984 | CO8: 46.446416 | CP8: 0.025183018 | CQ8: 2.8754536 | CR8: 0.52568438 | CS8: 18.941549 | CT8: 14.99909 | CU8: 42.734143 | CV8: 60.095026 | CW8: 18.48284 | CX8: 3.4862807 | CY8: 3.5241192 | CZ8: 43.136503 | DA8: 9.9397097 | DB8: 14.931148 | DC8: 0.3561592 | DD8: 0.15900909 | DE8: 0.97433489 | DF8: 1.4485137 | DG8: 6.9285451 | DH8: 5227.7755 | DI8: 445.42273 | DJ8: 5953.6768 | DK8: 0 | DL8: 141.53321 | DM8: 7.139189 | DN8: 87.740654 | DO8: 0 | DQ8: =SUM(DL8:DN8) -> 236.41305 | DR8: =DQ8/SUM(DQ$4:DQ$57) -> 0.00023002764
A9: EU | B9: Sector | C9: Mining & Quarrying of raw materials | D9: 250.34178 | E9: 179.99094 | F9: 15.633115 | G9: 58.73029 | H9: 49.880604 | I9: 3734.3365 | J9: 204.8189 | K9: 630.29165 | L9: 2.6743811 | M9: 79.811095 | N9: 39.462919 | O9: 17.014555 | P9: 115.56906 | Q9: 307.82808 | R9: 344.94947 | S9: 99.257143 | T9: 415.80809 | U9: 149.09865 | V9: 1413.713 | W9: 295.28909 | X9: 1139.9364 | Y9: 24.6696 | Z9: 3715.6973 | AA9: 6271.028 | AB9: 1587.931 | AC9: 6731.704 | AD9: 361.01916 | AE9: 2545.6808 | AF9: 195.52211 | AG9: 58.305495 | AH9: 138.87726 | AI9: 21.46758 | AJ9: 156.14668 | AK9: 357.57985 | AL9: 126.84477 | AM9: 15689.708 | AN9: 0.15188906 | AO9: 34.336889 | AP9: 33.046904 | AQ9: 695.45494 | AR9: 197.21307 | AS9: 607.19654 | AT9: 700.65161 | AU9: 270.42586 | AV9: 50.034857 | AW9: 51.787679 | AX9: 953.99528 | AY9: 42.774848 | AZ9: 121.54988 | BA9: 90.090041 | BB9: 41.022572 | BC9: 31.11142 | BD9: 68.621457 | BE9: 69.225751 | BF9: 25.820393 | BG9: 12.829301 | BH9: 4.2590738 | BI9: 17.762812 | BJ9: 47.037 | BK9: 219.34005 | BL9: 29.62026 | BM9: 31.335019 | BN9: 1.7766631 | BO9: 32.69568 | BP9: 3.7950264 | BQ9: 0.2366714 | BR9: 3.1562956 | BS9: 1.025123 | BT9: 16.667719 | BU9: 54.084865 | BV9: 27.645828 | BW9: 1.6776132 | BX9: 727.86213 | BY9: 22.97252 | BZ9: 120.50074 | CA9: 0.12191388 | CB9: 205.01338 | CC9: 124.36726 | CD9: 4.2476948 | CE9: 808.12575 | CF9: 7.5279926 | CG9: 336.53464 | CH9: 124.41524 | CI9: 2.5326863 | CJ9: 6.8946001 | CK9: 13.905337 | CL9: 2.4017948 | CM9: 5.5061331 | CN9: 1.9318749 | CO9: 612.16352 | CP9: 0.00039235857 | CQ9: 6.3350299 | CR9: 1.0640407 | CS9: 19.203544 | CT9: 34.759035 | CU9: 28.206573 | CV9: 80.922111 | CW9: 55.420003 | CX9: 18.089259 | CY9: 4.505931 | CZ9: 26.41693 | DA9: 67.054742 | DB9: 97.133831 | DC9: 0.63365617 | DD9: 0.25200119 | DE9: 1.4372561 | DF9: 5.1982267 | DG9: 21.61133 | DH9: 1586.9032 | DI9: 114.54862 | DJ9: 3317.4548 | DK9: 0 | DL9: 238.55977 | DM9: 5.3827142 | DN9: 271.64934 | DO9: 0 | DQ9: =SUM(DL9:DN9) -> 515.59183 | DR9: =DQ9/SUM(DQ$4:DQ$57) -> 0.00050166593
A10: EU | B10: Sector | C10: Processing of meat | D10: 58.805964 | E10: 9946.4529 | F10: 28.827743 | G10: 169.57015 | H10: 22.582744 | I10: 101.91465 | J10: 25945.669 | K10: 25075.896 | L10: 39.319898 | M10: 528.22914 | N10: 40.59153 | O10: 15.03719 | P10: 12.430162 | Q10: 29.807955 | R10: 177.47816 | S10: 102.76103 | T10: 626.36658 | U10: 214.74827 | V10: 313.70574 | W10: 251.5576 | X10: 7.9699982 | Y10: 3.1329445 | Z10: 53.286811 | AA10: 26.467305 | AB10: 7.0279191 | AC10: 65.948199 | AD10: 36.499292 | AE10: 674.10749 | AF10: 130.60992 | AG10: 41.51797 | AH10: 90.036854 | AI10: 18.03651 | AJ10: 62.764418 | AK10: 44.678338 | AL10: 37.889747 | AM10: 464.20557 | AN10: 0.098014878 | AO10: 84.458272 | AP10: 80.529575 | AQ10: 1409.9657 | AR10: 23595.967 | AS10: 1120.9493 | AT10: 2188.3743 | AU10: 408.63745 | AV10: 196.00266 | AW10: 334.63302 | AX10: 1402.9292 | AY10: 1513.1631 | AZ10: 5199.1322 | BA10: 22.768952 | BB10: 9.4415421 | BC10: 10.662515 | BD10: 20.162864 | BE10: 361.80708 | BF10: 184.71959 | BG10: 569.12413 | BH10: 5.2233858 | BI10: 105.96036 | BJ10: 42.592822 | BK10: 16.667262 | BL10: 2365.956 | BM10: 2785.3465 | BN10: 5.5053063 | BO10: 179.5585 | BP10: 4.0508118 | BQ10: 0.28692511 | BR10: 1.9666661 | BS10: 3.4792392 | BT10: 31.816169 | BU10: 22.901444 | BV10: 27.779425 | BW10: 3.1415629 | BX10: 961.62151 | BY10: 41.941335 | BZ10: 3.0241912 | CA10: 0.28434039 | CB10: 11.25933 | CC10: 3.3404822 | CD10: 0.42889634 | CE10: 19.201804 | CF10: 4.1956142 | CG10: 202.10311 | CH10: 12.344112 | CI10: 12.081562 | CJ10: 19.41272 | CK10: 4.3346015 | CL10: 6.0295486 | CM10: 5.406553 | CN10: 3.8645703 | CO10: 34.568085 | CP10: 0.0029767855 | CQ10: 9.9907894 | CR10: 6.8499649 | CS10: 113.64539 | CT10: 2977.1509 | CU10: 95.333378 | CV10: 208.32399 | CW10: 28.011597 | CX10: 106.50484 | CY10: 22.749944 | CZ10: 244.34646 | DA10: 144.10386 | DB10: 649.29965 | DC10: 0.87931145 | DD10: 0.72107087 | DE10: 3.1979035 | DF10: 4.4395441 | DG10: 69.765458 | DH10: 231893.02 | DI10: 829.84077 | DJ10: 2721.3509 | DK10: 0 | DL10: 24667.798 | DM10: 27.683211 | DN10: 179.45972 | DO10: 0 | DQ10: =SUM(DL10:DN10) -> 24874.94 | DR10: =DQ10/SUM(DQ$4:DQ$57) -> 0.02420308
A11: EU | B11: Sector | C11: Processing of other food&beverage | D11: 35.091975 | E11: 21828.082 | F11: 46.488174 | G11: 191.18499 | H11: 27.384445 | I11: 114.43386 | J11: 21193.129 | K11: 37420.895 | L11: 35.85414 | M11: 1561.5123 | N11: 71.060481 | O11: 24.782315 | P11: 18.665851 | Q11: 45.042256 | R11: 418.21659 | S11: 141.28291 | T11: 2158.8044 | U11: 458.66961 | V11: 1239.7135 | W11: 228.32223 | X11: 5.8468107 | Y11: 2.3655345 | Z11: 102.57716 | AA11: 24.748507 | AB11: 5.2629687 | AC11: 116.37395 | AD11: 48.647335 | AE11: 808.38688 | AF11: 195.49401 | AG11: 71.038236 | AH11: 188.52804 | AI11: 22.608165 | AJ11: 65.1205 | AK11: 58.124853 | AL11: 67.966103 | AM11: 923.92899 | AN11: 0.053113967 | AO11: 105.04075 | AP11: 99.445998 | AQ11: 1283.0654 | AR11: 27304.29 | AS11: 1088.0615 | AT11: 2287.8927 | AU11: 380.16878 | AV11: 201.49585 | AW11: 310.40028 | AX11: 1675.9327 | AY11: 1725.767 | AZ11: 6595.9136 | BA11: 28.849842 | BB11: 8.4462802 | BC11: 22.820355 | BD11: 38.875271 | BE11: 395.99104 | BF11: 74.770485 | BG11: 1421.9148 | BH11: 15.363134 | BI11: 97.254468 | BJ11: 44.83621 | BK11: 25.501136 | BL11: 894.27459 | BM11: 4620.7073 | BN11: 7.3126645 | BO11: 180.32862 | BP11: 7.4632118 | BQ11: 0.3765732 | BR11: 2.7256164 | BS11: 4.8295119 | BT11: 46.892794 | BU11: 44.139059 | BV11: 27.202865 | BW11: 3.1679531 | BX11: 720.86317 | BY11: 62.284496 | BZ11: 4.3806688 | CA11: 0.30419467 | CB11: 13.472863 | CC11: 6.1843891 | CD11: 0.48858584 | CE11: 37.805242 | CF11: 5.6127741 | CG11: 225.51506 | CH11: 30.137499 | CI11: 11.79447 | CJ11: 24.478567 | CK11: 7.770822 | CL11: 12.832394 | CM11: 9.3753973 | CN11: 6.3139901 | CO11: 391.08402 | CP11: 0.0027557813 | CQ11: 16.703691 | CR11: 8.4665799 | CS11: 232.82389 | CT11: 5172.621 | CU11: 291.32907 | CV11: 261.31908 | CW11: 31.861019 | CX11: 52.933018 | CY11: 28.200022 | CZ11: 240.79609 | DA11: 176.58927 | DB11: 644.43082 | DC11: 0.88207775 | DD11: 0.58988714 | DE11: 1.4465938 | DF11: 12.015496 | DG11: 84.382827 | DH11: 302148.24 | DI11: 778.89246 | DJ11: 3807.3481 | DK11: 0 | DL11: 41634.874 | DM11: 78.812984 | DN11: 267.34237 | DO11: 0 | DQ11: =SUM(DL11:DN11) -> 41981.029 | DR11: =DQ11/SUM(DQ$4:DQ$57) -> 0.040847141
A12: EU | B12: Sector | C12: Manufacture of tobacco products (16) | D12: 8.1863784 | E12: 19.030173 | F12: 1.5328489 | G12: 0.54117537 | H12: 3.4815553 | I12: 1.4746285 | J12: 32.055095 | K12: 28.224828 | L12: 394.20187 | M12: 14.412492 | N12: 1.3229335 | O12: 2.1622269 | P12: 0.72904948 | Q12: 0.87405367 | R12: 23.390313 | S12: 8.2697352 | T12: 9.735365 | U12: 2.7489574 | V12: 9.8939249 | W12: 8.9380885 | X12: 0.39505872 | Y12: 0.11342645 | Z12: 0.94379619 | AA12: 1.193906 | AB12: 0.38657757 | AC12: 499.85047 | AD12: 52.283513 | AE12: 94.832694 | AF12: 4.7158061 | AG12: 0.66697464 | AH12: 9.4105658 | AI12: 2.083574 | AJ12: 1.8817353 | AK12: 5.8336991 | AL12: 1.2266984 | AM12: 76.115044 | AN12: 0.0046872732 | AO12: 6.6933062 | AP12: 1.0874854 | AQ12: 191.97218 | AR12: 336.97189 | AS12: 57.181167 | AT12: 160.67751 | AU12: 12.918326 | AV12: 12.127279 | AW12: 9.0420482 | AX12: 119.84071 | AY12: 12.103816 | AZ12: 14.281576 | BA12: 2.8442876 | BB12: 0.62930708 | BC12: 2.3938085 | BD12: 3.0787067 | BE12: 65.015436 | BF12: 2.901668 | BG12: 0.85593995 | BH12: 1.2211282 | BI12: 0.25107351 | BJ12: 5.4624211 | BK12: 1.3129006 | BL12: 7.1260583 | BM12: 6.0879446 | BN12: 15.468399 | BO12: 3.9820979 | BP12: 0.56946757 | BQ12: 0.0062007486 | BR12: 0.032074718 | BS12: 0.012286288 | BT12: 2.147714 | BU12: 2.8471883 | BV12: 0.17883754 | BW12: 0.0074399297 | BX12: 60.897567 | BY12: 0.6814061 | BZ12: 0.67123333 | CA12: 0.0036177072 | CB12: 1.6903541 | CC12: 0.72852001 | CD12: 0.0046086029 | CE12: 32.364196 | CF12: 0.62497302 | CG12: 11.393804 | CH12: 2.1582867 | CI12: 0.73450851 | CJ12: 2.939429 | CK12: 0.72638464 | CL12: 0.66911117 | CM12: 3.7814635 | CN12: 0.32007213 | CO12: 4.0240029 | CP12: 0.00019807552 | CQ12: 1.2221965 | CR12: 1.0023078 | CS12: 4.7442714 | CT12: 12.104791 | CU12: 4.7121479 | CV12: 22.164601 | CW12: 4.1054518 | CX12: 4.2501378 | CY12: 1.3647683 | CZ12: 4.8156928 | DA12: 3.8465754 | DB12: 4.4804912 | DC12: 0.045271273 | DD12: 0.013472119 | DE12: 0.20120624 | DF12: 1.829319 | DG12: 4.9430783 | DH12: 12663.349 | DI12: 29.155915 | DJ12: 932.3822 | DK12: 0 | DL12: 3921.8808 | DM12: 0.28552523 | DN12: 10.197401 | DO12: 0 | DQ12: =SUM(DL12:DN12) -> 3932.3637 | DR12: =DQ12/SUM(DQ$4:DQ$57) -> 0.0038261524
A13: EU | B13: Sector | C13: Manufacture of textiles | D13: 371.49919 | E13: 221.32103 | F13: 72.31161 | G13: 230.70512 | H13: 78.36393 | I13: 65.069363 | J13: 182.12319 | K13: 463.1606 | L13: 35.659937 | M13: 49068.039 | N13: 218.01207 | O13: 147.8436 | P13: 37.266879 | Q13: 101.54048 | R13: 1267.9428 | S13: 50.918614 | T13: 350.69854 | U13: 85.18997 | V13: 697.05688 | W13: 1930.1103 | X13: 92.682026 | Y13: 35.486118 | Z13: 146.42225 | AA13: 95.519743 | AB13: 22.202565 | AC13: 285.84196 | AD13: 115.47454 | AE13: 6727.1397 | AF13: 1979.0189 | AG13: 84.805374 | AH13: 143.04041 | AI13: 19.309961 | AJ13: 106.65939 | AK13: 102.97724 | AL13: 69.646438 | AM13: 2424.0763 | AN13: 1.2742648 | AO13: 209.30895 | AP13: 57.520669 | AQ13: 769.32546 | AR13: 2479.5657 | AS13: 776.30519 | AT13: 1683.5293 | AU13: 174.1794 | AV13: 199.793 | AW13: 109.96754 | AX13: 1173.6202 | AY13: 217.48317 | AZ13: 1773.1272 | BA13: 112.77695 | BB13: 44.504999 | BC13: 42.041543 | BD13: 117.02123 | BE13: 683.63787 | BF13: 112.43947 | BG13: 34.172124 | BH13: 11.447789 | BI13: 48.834674 | BJ13: 88.291976 | BK13: 47.031349 | BL13: 30.225666 | BM13: 72.930613 | BN13: 19.871447 | BO13: 8279.7765 | BP13: 29.13419 | BQ13: 0.63665695 | BR13: 3.8923937 | BS13: 1.5680017 | BT13: 242.92135 | BU13: 28.568648 | BV13: 26.825363 | BW13: 1.8463209 | BX13: 3100.1556 | BY13: 290.51742 | BZ13: 15.600197 | CA13: 0.50023436 | CB13: 30.087131 | CC13: 9.8366416 | CD13: 0.18652538 | CE13: 61.239047 | CF13: 1.2909601 | CG13: 947.44941 | CH13: 506.638 | CI13: 13.710141 | CJ13: 22.181791 | CK13: 12.608782 | CL13: 16.447233 | CM13: 11.974498 | CN13: 9.6345734 | CO13: 1137.6255 | CP13: 0.041047299 | CQ13: 40.996489 | CR13: 8.2582067 | CS13: 349.65835 | CT13: 351.22317 | CU13: 176.88717 | CV13: 292.50165 | CW13: 48.409161 | CX13: 40.159466 | CY13: 84.280082 | CZ13: 383.48915 | DA13: 106.88106 | DB13: 472.85777 | DC13: 12.415784 | DD13: 3.7901919 | DE13: 9.3007188 | DF13: 20.344872 | DG13: 175.94743 | DH13: 135292.6 | DI13: 755.84039 | DJ13: 4510.4066 | DK13: 0 | DL13: 34673.503 | DM13: 44.046308 | DN13: 1129.0517 | DO13: 0 | DQ13: =SUM(DL13:DN13) -> 35846.601 | DR13: =DQ13/SUM(DQ$4:DQ$57) -> 0.034878401
A14: EU | B14: Sector | C14: Manufacture of wood and of products of wood and cork, except furniture; manufacture of articles of straw and plaiting materials (20) | D14: 474.76783 | E14: 261.18483 | F14: 197.07972 | G14: 63.972492 | H14: 192.12067 | I14: 183.30699 | J14: 288.22086 | K14: 802.36148 | L14: 25.256434 | M14: 249.87107 | N14: 14272.054 | O14: 4482.2295 | P14: 410.44403 | Q14: 24.080978 | R14: 1323.9192 | S14: 46.977583 | T14: 352.29251 | U14: 84.122181 | V14: 78.742924 | W14: 493.10941 | X14: 129.18915 | Y14: 50.647641 | Z14: 560.12934 | AA14: 103.08586 | AB14: 28.312258 | AC14: 762.14371 | AD14: 366.60625 | AE14: 4955.6325 | AF14: 8890.8995 | AG14: 199.00379 | AH14: 347.89556 | AI14: 187.53144 | AJ14: 531.12974 | AK14: 70.584178 | AL14: 231.92295 | AM14: 23646.72 | AN14: 0.28646851 | AO14: 92.328858 | AP14: 22.907399 | AQ14: 498.00198 | AR14: 1398.239 | AS14: 778.44139 | AT14: 1533.8929 | AU14: 2049.5465 | AV14: 109.24146 | AW14: 72.262706 | AX14: 316.3958 | AY14: 242.84433 | AZ14: 222.72734 | BA14: 101.04183 | BB14: 41.136455 | BC14: 20.623376 | BD14: 35.98606 | BE14: 893.45071 | BF14: 23.826026 | BG14: 7.4897438 | BH14: 8.6205345 | BI14: 7.1919717 | BJ14: 32.442825 | BK14: 11.42499 | BL14: 20.031091 | BM14: 41.485522 | BN14: 7.7093016 | BO14: 25.61705 | BP14: 1359.0607 | BQ14: 329.54374 | BR14: 199.72104 | BS14: 0.69971063 | BT14: 219.27005 | BU14: 10.399118 | BV14: 13.300209 | BW14: 1.9745504 | BX14: 104.97488 | BY14: 38.718728 | BZ14: 17.279709 | CA14: 2.0503282 | CB14: 34.812515 | CC14: 5.0135764 | CD14: 0.79036234 | CE14: 49.513584 | CF14: 1.2211404 | CG14: 438.12504 | CH14: 884.12681 | CI14: 5.4382919 | CJ14: 2.6303668 | CK14: 4.4660448 | CL14: 4.5197122 | CM14: 2.07703 | CN14: 1.9339227 | CO14: 5019.976 | CP14: 0.00066899757 | CQ14: 12.973149 | CR14: 1.9143683 | CS14: 78.050173 | CT14: 95.541118 | CU14: 68.139056 | CV14: 118.1542 | CW14: 276.63998 | CX14: 13.170551 | CY14: 6.5286129 | CZ14: 109.59524 | DA14: 50.329916 | DB14: 42.792421 | DC14: 4.6318643 | DD14: 1.4250472 | DE14: 1.6759654 | DF14: 1.65526 | DG14: 28.703784 | DH14: 10427.412 | DI14: 84.393385 | DJ14: 8824.3183 | DK14: 0 | DL14: 1298.8994 | DM14: 2.217063 | DN14: 1033.4581 | DO14: 0 | DQ14: =SUM(DL14:DN14) -> 2334.5746 | DR14: =DQ14/SUM(DQ$4:DQ$57) -> 0.0022715188
A15: EU | B15: Sector | C15: Re-processing of secondary wood material into new wood material | D15: 204.54395 | E15: 105.47208 | F15: 40.056046 | G15: 23.009819 | H15: 51.961684 | I15: 63.781712 | J15: 124.53545 | K15: 354.26046 | L15: 8.4400313 | M15: 109.89879 | N15: 3900.7583 | O15: 2253.6477 | P15: 65.765141 | Q15: 7.9020116 | R15: 275.68985 | S15: 12.022656 | T15: 131.10101 | U15: 43.337618 | V15: 26.20708 | W15: 209.36727 | X15: 38.965028 | Y15: 21.679378 | Z15: 200.87417 | AA15: 33.556714 | AB15: 9.3013539 | AC15: 152.80323 | AD15: 77.063775 | AE15: 1793.9995 | AF15: 3614.7705 | AG15: 65.829287 | AH15: 44.052379 | AI15: 13.086412 | AJ15: 65.26426 | AK15: 24.610402 | AL15: 22.904805 | AM15: 8451.241 | AN15: 0.059242666 | AO15: 34.108725 | AP15: 8.9582682 | AQ15: 182.59749 | AR15: 507.89005 | AS15: 256.10045 | AT15: 740.27321 | AU15: 458.30898 | AV15: 49.660243 | AW15: 12.088397 | AX15: 110.21048 | AY15: 64.794489 | AZ15: 74.976407 | BA15: 31.471748 | BB15: 13.562269 | BC15: 5.0911612 | BD15: 9.1498173 | BE15: 380.94061 | BF15: 6.2210044 | BG15: 1.448438 | BH15: 2.0366288 | BI15: 1.3296304 | BJ15: 8.2916732 | BK15: 3.2591703 | BL15: 6.0741803 | BM15: 12.262175 | BN15: 2.4317991 | BO15: 8.3379596 | BP15: 291.12399 | BQ15: 65.481491 | BR15: 30.671739 | BS15: 0.19852183 | BT15: 56.510476 | BU15: 1.8017896 | BV15: 2.8540624 | BW15: 0.41585097 | BX15: 30.666094 | BY15: 12.858519 | BZ15: 3.9727872 | CA15: 0.41807311 | CB15: 7.8493149 | CC15: 1.3046386 | CD15: 0.16446713 | CE15: 14.930336 | CF15: 0.31336403 | CG15: 123.73708 | CH15: 204.75117 | CI15: 1.209098 | CJ15: 0.81415775 | CK15: 0.73684078 | CL15: 0.78856426 | CM15: 0.72687004 | CN15: 0.47338956 | CO15: 916.71143 | CP15: 0.00022564739 | CQ15: 3.5636092 | CR15: 0.41266439 | CS15: 19.506345 | CT15: 20.736687 | CU15: 17.98941 | CV15: 31.221379 | CW15: 41.0504 | CX15: 4.0235607 | CY15: 2.1802471 | CZ15: 26.88843 | DA15: 11.570458 | DB15: 10.935117 | DC15: 1.1761464 | DD15: 0.3896534 | DE15: 0.5345988 | DF15: 0.41624913 | DG15: 6.9335944 | DH15: 3737.491 | DI15: 31.353547 | DJ15: 3211.0441 | DK15: 0 | DL15: 343.03997 | DM15: 0.49500641 | DN15: 248.47679 | DO15: 0 | DQ15: =SUM(DL15:DN15) -> 592.01176 | DR15: =DQ15/SUM(DQ$4:DQ$57) -> 0.0005760218
... A57: EU | B57: Sector | C57: Other Services | D57: 1216.5493 | E57: 165.5005 | F57: 427.84517 | G57: 26.767906 | H57: 579.31785 | I57: 315.08928 | J57: 472.69992 | K57: 1685.8197 | L57: 410.08334 | M57: 1218.3911 | N57: 300.00987 | O57: 41.331096 | P57: 39.045318 | Q57: 45.276706 | R57: 702.40543 | S57: 292.21758 | T57: 232.23895 | U57: 68.253084 | V57: 1166.4106 | W57: 254.87064 | X57: 42.561479 | Y57: 11.2911 | Z57: 182.83607 | AA57: 135.06765 | AB57: 43.361847 | AC57: 400.69483 | AD57: 102.43453 | AE57: 3614.1243 | AF57: 387.52206 | AG57: 31.68988 | AH57: 204.37842 | AI57: 68.882316 | AJ57: 129.02702 | AK57: 362.09984 | AL57: 270.61433 | AM57: 968.46392 | AN57: 3.3540029 | AO57: 163.75812 | AP57: 36.213145 | AQ57: 301.98596 | AR57: 2690.7045 | AS57: 1372.6381 | AT57: 6836.2686 | AU57: 1152.3105 | AV57: 581.60328 | AW57: 271.30901 | AX57: 478.54698 | AY57: 464.92999 | AZ57: 3737.8001 | BA57: 321.60241 | BB57: 112.53544 | BC57: 60.871951 | BD57: 60.580274 | BE57: 9037.9422 | BF57: 12.031771 | BG57: 3.0901706 | BH57: 1.2978098 | BI57: 2.8987984 | BJ57: 13.860356 | BK57: 5.7754294 | BL57: 13.82242 | BM57: 39.620544 | BN57: 1.577209 | BO57: 17.228093 | BP57: 5.9455312 | BQ57: 0.97512069 | BR57: 0.9937224 | BS57: 0.067857693 | BT57: 25.792687 | BU57: 4.6832736 | BV57: 1.3940201 | BW57: 0.050285669 | BX57: 49.863617 | BY57: 5.0876467 | BZ57: 2.1895291 | CA57: 0.016306684 | CB57: 7.643125 | CC57: 1.9060239 | CD57: 0.12007093 | CE57: 18.31853 | CF57: 0.8736201 | CG57: 96.325823 | CH57: 7.6201822 | CI57: 4.4822268 | CJ57: 9.4882659 | CK57: 2.9593147 | CL57: 2.1071319 | CM57: 1.7183915 | CN57: 1.620795 | CO57: 37.118334 | CP57: 0.00108283 | CQ57: 9.4561064 | CR57: 0.56500121 | CS57: 27.092587 | CT57: 36.655045 | CU57: 49.145919 | CV57: 113.38611 | CW57: 15.546318 | CX57: 6.9826371 | CY57: 4.6992926 | CZ57: 35.425946 | DA57: 16.591315 | DB57: 32.201038 | DC57: 4.0896015 | DD57: 0.37754447 | DE57: 3.6307949 | DF57: 1.874465 | DG57: 37.992956 | DH57: 306568.43 | DI57: 3732.278 | DJ57: 489.62977 | DK57: 0 | DL57: 40220.69 | DM57: 23.312053 | DN57: 91.67345 | DO57: 0 | DQ57: =SUM(DL57:DN57) -> 40335.675 | DR57: =DQ57/SUM(DQ$4:DQ$57) -> 0.039246227
A58: RoW | B58: Sector | C58: Agriculture | D58: 1072.8292 | E58: 5042.5051 | F58: 421.1424 | G58: 12.790195 | H58: 19.354915 | I58: 15.954901 | J58: 2694.0135 | K58: 11209.655 | L58: 1942.8917 | M58: 1145.6751 | N58: 46.198055 | O58: 23.62128 | P58: 6.8652358 | Q58: 23.76148 | R58: 74.042597 | S58: 216.68842 | T58: 283.50567 | U58: 109.79243 | V58: 116.01161 | W58: 79.381027 | X58: 7.2449682 | Y58: 2.2907201 | Z58: 29.156012 | AA58: 11.727064 | AB58: 3.2767229 | AC58: 143.74429 | AD58: 55.736253 | AE58: 378.32006 | AF58: 38.779616 | AG58: 9.8908593 | AH58: 32.360279 | AI58: 49.865064 | AJ58: 10.905282 | AK58: 15.929343 | AL58: 17.718292 | AM58: 319.36794 | AN58: 0.014272489 | AO58: 15.701879 | AP58: 12.209346 | AQ58: 494.58814 | AR58: 1366.7677 | AS58: 379.2496 | AT58: 380.89176 | AU58: 25.965953 | AV58: 14.113475 | AW58: 25.498768 | AX58: 211.7717 | AY58: 40.812264 | AZ58: 678.8267 | BA58: 17.075118 | BB58: 1.8607167 | BC58: 2.9700217 | BD58: 4.5554931 | BE58: 88.797713 | BF58: 163093.76 | BG58: 75964.53 | BH58: 5360.9307 | BI58: 1037.1516 | BJ58: 4362.1294 | BK58: 1712.9096 | BL58: 71672.125 | BM58: 462651.2 | BN58: 26325.897 | BO58: 42974.445 | BP58: 5394.2838 | BQ58: 12.886878 | BR58: 1636.929 | BS58: 4.5303286 | BT58: 8098.6947 | BU58: 1018.13 | BV58: 14249.195 | BW58: 9.9708276 | BX58: 59804.099 | BY58: 2105.8726 | BZ58: 277.04117 | CA58: 0.61578764 | CB58: 1068.5231 | CC58: 247.00681 | CD58: 0.37339647 | CE58: 2622.419 | CF58: 11.318555 | CG58: 4394.712 | CH58: 1045.4772 | CI58: 470.48626 | CJ58: 1307.8409 | CK58: 355.00698 | CL58: 803.03754 | CM58: 1224.3061 | CN58: 293.05627 | CO58: 25208.231 | CP58: 0.021244303 | CQ58: 636.25481 | CR58: 545.67904 | CS58: 4181.4507 | CT58: 57459.378 | CU58: 4098.9303 | CV58: 7429.5926 | CW58: 5218.5911 | CX58: 1409.9514 | CY58: 1580.7775 | CZ58: 4668.4547 | DA58: 3065.0941 | DB58: 13333.082 | DC58: 47.8598 | DD58: 22.325793 | DE58: 175.30863 | DF58: 1135.4392 | DG58: 7123.0298 | DH58: 33630.685 | DI58: 182.39294 | DJ58: 1595.8359 | DK58: 0 | DL58: 672489.13 | DM58: 11091.222 | DN58: 30464.006 | DO58: 0 | DQ58: =SUM(DH58:DJ58) -> 35408.914 | DR58: =DQ58/SUM(DQ$58:DQ$111) -> 0.053361169
A59: RoW | B59: Sector | C59: Animal Farming | D59: 118.38491 | E59: 144.10895 | F59: 11.952181 | G59: 5.8850376 | H59: 16.755397 | I59: 8.7494162 | J59: 296.96875 | K59: 483.89313 | L59: 33.663542 | M59: 75.248848 | N59: 29.804514 | O59: 14.220332 | P59: 3.9111106 | Q59: 10.210287 | R59: 22.100835 | S59: 201.18014 | T59: 114.61778 | U59: 46.671662 | V59: 67.120725 | W59: 40.531341 | X59: 4.3125878 | Y59: 1.3716758 | Z59: 15.549836 | AA59: 6.7215616 | AB59: 1.9729714 | AC59: 47.690329 | AD59: 14.913138 | AE59: 119.10282 | AF59: 20.718637 | AG59: 4.1669244 | AH59: 25.248495 | AI59: 3.2895097 | AJ59: 6.1072205 | AK59: 16.401012 | AL59: 9.8675667 | AM59: 69.766011 | AN59: 0.012004229 | AO59: 7.3229202 | AP59: 4.7961312 | AQ59: 81.97041 | AR59: 270.74901 | AS59: 80.439521 | AT59: 92.613967 | AU59: 13.527714 | AV59: 6.8233551 | AW59: 14.603172 | AX59: 37.776845 | AY59: 12.92303 | AZ59: 158.2429 | BA59: 6.121757 | BB59: 2.1850104 | BC59: 2.2419528 | BD59: 4.0893561 | BE59: 66.418324 | BF59: 1696.3886 | BG59: 126741.52 | BH59: 878.76905 | BI59: 1120.5451 | BJ59: 2208.1581 | BK59: 1676.6081 | BL59: 317291.24 | BM59: 50937.996 | BN59: 669.67945 | BO59: 17620.531 | BP59: 420.30431 | BQ59: 3.556918 | BR59: 121.0018 | BS59: 1.904114 | BT59: 745.21876 | BU59: 1216.8993 | BV59: 207.53434 | BW59: 2.9048454 | BX59: 16556.606 | BY59: 1811.1291 | BZ59: 245.70133 | CA59: 0.29031026 | CB59: 441.39934 | CC59: 242.22936 | CD59: 0.38137173 | CE59: 1514.1469 | CF59: 5.757041 | CG59: 2686.2389 | CH59: 5692.0684 | CI59: 455.01017 | CJ59: 651.12292 | CK59: 257.97597 | CL59: 470.14618 | CM59: 757.67488 | CN59: 295.55935 | CO59: 4135.6785 | CP59: 0.03226154 | CQ59: 599.33183 | CR59: 348.77517 | CS59: 4424.0755 | CT59: 38159.771 | CU59: 16730.408 | CV59: 4189.7822 | CW59: 1325.029 | CX59: 1108.7294 | CY59: 1662.9123 | CZ59: 5108.7686 | DA59: 2863.6973 | DB59: 3825.2789 | DC59: 99.990465 | DD59: 46.108052 | DE59: 889.01831 | DF59: 833.14191 | DG59: 2519.5509 | DH59: 2240.8765 | DI59: 73.52287 | DJ59: 348.40819 | DK59: 0 | DL59: 199679.12 | DM59: 8086.4068 | DN59: 91918.778 | DO59: 0 | DQ59: =SUM(DH59:DJ59) -> 2662.8075 | DR59: =DQ59/SUM(DQ$58:DQ$111) -> 0.0040128461
A60: RoW | B60: Sector | C60: Forestry, logging and related service activities (02) | D60: 9.3175023 | E60: 11.28869 | F60: 158.52501 | G60: 0.52519395 | H60: 2.4054583 | I60: 2.4247076 | J60: 14.213955 | K60: 47.851875 | L60: 1.0712178 | M60: 5.6596826 | N60: 424.94767 | O60: 9.0196838 | P60: 89.472536 | Q60: 2.2154704 | R60: 262.24835 | S60: 3.2361123 | T60: 13.408167 | U60: 7.4670679 | V60: 13.917919 | W60: 10.718435 | X60: 1.1447482 | Y60: 0.45651489 | Z60: 5.3191244 | AA60: 2.5237254 | AB60: 0.69929383 | AC60: 4.53838 | AD60: 2.0301254 | AE60: 17.474865 | AF60: 35.309755 | AG60: 0.54393279 | AH60: 2.2073322 | AI60: 6.9136945 | AJ60: 0.9099684 | AK60: 0.78672776 | AL60: 1.04686 | AM60: 31.428943 | AN60: 0.0035101443 | AO60: 1.5818679 | AP60: 0.20651902 | AQ60: 11.455941 | AR60: 11.817083 | AS60: 6.5518904 | AT60: 25.685464 | AU60: 3.5971548 | AV60: 0.68022802 | AW60: 1.913318 | AX60: 123.38141 | AY60: 1.5679562 | AZ60: 14.732965 | BA60: 0.74399788 | BB60: 0.27523085 | BC60: 0.33878332 | BD60: 0.73604721 | BE60: 3.646363 | BF60: 1111.0335 | BG60: 325.10732 | BH60: 23245.519 | BI60: 45.942565 | BJ60: 1520.5933 | BK60: 98.868865 | BL60: 773.92837 | BM60: 3360.811 | BN60: 344.66086 | BO60: 2401.8996 | BP60: 56441.333 | BQ60: 29.197048 | BR60: 3010.802 | BS60: 4.8677564 | BT60: 26594.556 | BU60: 55.194812 | BV60: 71.634269 | BW60: 0.86834922 | BX60: 9728.4965 | BY60: 12400.968 | BZ60: 26.407771 | CA60: 2.4670208 | CB60: 100.91137 | CC60: 12.559488 | CD60: 0.078716173 | CE60: 79.777949 | CF60: 0.72755715 | CG60: 350.84843 | CH60: 4606.8003 | CI60: 132.99626 | CJ60: 20.365958 | CK60: 24.664031 | CL60: 16.411947 | CM60: 5.5523312 | CN60: 4.3020802 | CO60: 15349.717 | CP60: 0.0054996105 | CQ60: 23.09655 | CR60: 1.4847328 | CS60: 198.02538 | CT60: 1344.2616 | CU60: 1574.4096 | CV60: 239.26057 | CW60: 81.380056 | CX60: 21.316828 | CY60: 454.10574 | CZ60: 389.37184 | DA60: 79.788395 | DB60: 197.23118 | DC60: 6.1301225 | DD60: 4.1048418 | DE60: 5.5830223 | DF60: 12.572326 | DG60: 93.177106 | DH60: 230.6586 | DI60: 12.298189 | DJ60: 116.18041 | DK60: 0 | DL60: 42348.051 | DM60: 264.55897 | DN60: 7621.564 | DO60: 0 | DQ60: =SUM(DH60:DJ60) -> 359.1372 | DR60: =DQ60/SUM(DQ$58:DQ$111) -> 0.00054121911
A61: RoW | B61: Sector | C61: Fishing, operating of fish hatcheries and fish farms; service activities incidental to fishing (05) | D61: 1.7651894 | E61: 12.499006 | F61: 1.0882657 | G61: 70.151216 | H61: 0.42465527 | I61: 0.39943946 | J61: 692.67944 | K61: 917.877 | L61: 6.3185745 | M61: 5.2342339 | N61: 3.1879761 | O61: 1.7691468 | P61: 0.15817648 | Q61: 0.32015962 | R61: 1.6507322 | S61: 1.349972 | T61: 9.0065027 | U61: 3.8312681 | V61: 5.1583845 | W61: 1.4296329 | X61: 0.1808623 | Y61: 0.10329719 | Z61: 0.5957934 | AA61: 0.29907244 | AB61: 0.13258575 | AC61: 1.5525912 | AD61: 0.45983525 | AE61: 10.272637 | AF61: 1.901156 | AG61: 0.3007671 | AH61: 0.65312533 | AI61: 0.16566113 | AJ61: 0.39694237 | AK61: 0.23370185 | AL61: 0.32267252 | AM61: 6.1367556 | AN61: 0.0010651702 | AO61: 1.469321 | AP61: 0.50525836 | AQ61: 21.642193 | AR61: 358.50099 | AS61: 25.257821 | AT61: 14.54077 | AU61: 2.3668358 | AV61: 1.3210283 | AW61: 1.4504845 | AX61: 6.9683502 | AY61: 5.1938446 | AZ61: 30.927781 | BA61: 0.30549432 | BB61: 0.11463286 | BC61: 0.078700077 | BD61: 0.1931248 | BE61: 2.7325242 | BF61: 769.6079 | BG61: 605.15014 | BH61: 71.443761 | BI61: 6276.9588 | BJ61: 158.42094 | BK61: 153.821 | BL61: 193685.95 | BM61: 3100.3481 | BN61: 58.744864 | BO61: 252.71086 | BP61: 42.668079 | BQ61: 0.61311989 | BR61: 12.843069 | BS61: 0.090210178 | BT61: 71.973269 | BU61: 50.118033 | BV61: 30.27224 | BW61: 0.082161868 | BX61: 2529.6076 | BY61: 13.392119 | BZ61: 18.746219 | CA61: 0.016716867 | CB61: 31.458912 | CC61: 13.358182 | CD61: 0.016930924 | CE61: 102.1182 | CF61: 0.14614009 | CG61: 235.87172 | CH61: 105.33283 | CI61: 30.743123 | CJ61: 119.13929 | CK61: 37.59809 | CL61: 64.160117 | CM61: 90.295439 | CN61: 31.3275 | CO61: 215.31162 | CP61: 0.00094892245 | CQ61: 105.76752 | CR61: 51.606319 | CS61: 613.71944 | CT61: 19765.628 | CU61: 694.01664 | CV61: 481.07322 | CW61: 112.61399 | CX61: 119.17652 | CY61: 96.442031 | CZ61: 252.52644 | DA61: 185.91562 | DB61: 1980.3744 | DC61: 3.0612005 | DD61: 1.8420203 | DE61: 3.7934337 | DF61: 95.286375 | DG61: 543.11361 | DH61: 3144.3506 | DI61: 5.5107608 | DJ61: 31.202717 | DK61: 0 | DL61: 57440.94 | DM61: 117.10438 | DN61: 3059.4967 | DO61: 0 | DQ61: =SUM(DH61:DJ61) -> 3181.0641 | DR61: =DQ61/SUM(DQ$58:DQ$111) -> 0.0047938579
A62: RoW | B62: Sector | C62: Extraction of Fossil-Fuels | D62: 337.54774 | E62: 111.33963 | F62: 14.974365 | G62: 21.126215 | H62: 5579.8109 | I62: 204.51122 | J62: 294.48339 | K62: 460.5324 | L62: 10.686349 | M62: 2286.2201 | N62: 829.24571 | O62: 170.68341 | P62: 131.6051 | Q62: 60.168076 | R62: 227.86376 | S62: 182568.41 | T62: 2935.512 | U62: 283.95627 | V62: 4687.4646 | W62: 1216.5494 | X62: 258.71064 | Y62: 21.18655 | Z62: 531.36928 | AA62: 444.00696 | AB62: 56.931695 | AC62: 2576.6115 | AD62: 245.82626 | AE62: 1696.4561 | AF62: 1727.6936 | AG62: 24.517999 | AH62: 18094.213 | AI62: 345.76255 | AJ62: 261.57634 | AK62: 10089.726 | AL62: 1834.9992 | AM62: 723.91497 | AN62: 0.18272893 | AO62: 68.780442 | AP62: 5.5369489 | AQ62: 538.50156 | AR62: 276.69892 | AS62: 1299.1543 | AT62: 814.73221 | AU62: 348.15053 | AV62: 45.941122 | AW62: 167.01897 | AX62: 935.95908 | AY62: 164.68942 | AZ62: 751.04124 | BA62: 34.140468 | BB62: 11.850654 | BC62: 18.925374 | BD62: 36.274557 | BE62: 192.31795 | BF62: 4354.6912 | BG62: 1069.5465 | BH62: 315.14448 | BI62: 378.38074 | BJ62: 204054.36 | BK62: 9128.1559 | BL62: 1467.3948 | BM62: 2003.3727 | BN62: 268.17723 | BO62: 15947.698 | BP62: 3255.1633 | BQ62: 370.35879 | BR62: 961.45812 | BS62: 34.55317 | BT62: 3889.1197 | BU62: 1069111.4 | BV62: 23278.931 | BW62: 32.439703 | BX62: 97406.459 | BY62: 17873.136 | BZ62: 1456.4817 | CA62: 10.909013 | CB62: 17203.71 | CC62: 25472.69 | CD62: 80.955109 | CE62: 44214.094 | CF62: 172.05752 | CG62: 16668.843 | CH62: 11613.358 | CI62: 161.01491 | CJ62: 163934.19 | CK62: 609.6033 | CL62: 913.44319 | CM62: 29422.076 | CN62: 1844.4153 | CO62: 16091.77 | CP62: 1.8293922 | CQ62: 816.075 | CR62: 174.50419 | CS62: 3604.0535 | CT62: 3317.2017 | CU62: 19852.38 | CV62: 11771.614 | CW62: 2422.265 | CX62: 855.81727 | CY62: 2469.5673 | CZ62: 11045.037 | DA62: 3159.2918 | DB62: 5754.6264 | DC62: 123.63413 | DD62: 89.10402 | DE62: 354.26032 | DF62: 711.44787 | DG62: 3050.9151 | DH62: 2416.9352 | DI62: 392.38548 | DJ62: 21083.117 | DK62: 0 | DL62: 80824.015 | DM62: 2171.3194 | DN62: 227533.73 | DO62: 0 | DQ62: =SUM(DH62:DJ62) -> 23892.438 | DR62: =DQ62/SUM(DQ$58:DQ$111) -> 0.036005861
A63: RoW | B63: Sector | C63: Mining & Quarrying of raw materials | D63: 255.23516 | E63: 150.63525 | F63: 6.0780671 | G63: 19.805559 | H63: 14.641149 | I63: 374.86354 | J63: 384.36764 | K63: 638.43688 | L63: 9.9187965 | M63: 133.74481 | N63: 30.370906 | O63: 17.384193 | P63: 16.745247 | Q63: 55.498256 | R63: 72.596184 | S63: 216.32879 | T63: 663.16848 | U63: 243.58012 | V63: 773.31578 | W63: 130.91026 | X63: 251.69328 | Y63: 13.562524 | Z63: 811.33759 | AA63: 322.23178 | AB63: 139.03162 | AC63: 12190.655 | AD63: 628.68135 | AE63: 824.48928 | AF63: 521.21189 | AG63: 23.488843 | AH63: 73.471502 | AI63: 6.694402 | AJ63: 33.625846 | AK63: 42.016415 | AL63: 28.563595 | AM63: 576.03837 | AN63: 0.037435026 | AO63: 15.846186 | AP63: 7.2063253 | AQ63: 149.76618 | AR63: 411.18292 | AS63: 92.745162 | AT63: 204.31129 | AU63: 24.440729 | AV63: 17.70379 | AW63: 59.032318 | AX63: 112.90529 | AY63: 35.643974 | AZ63: 387.05555 | BA63: 18.307493 | BB63: 6.3883583 | BC63: 7.0284777 | BD63: 11.324675 | BE63: 51.666236 | BF63: 2388.9144 | BG63: 1994.9943 | BH63: 407.24751 | BI63: 511.70613 | BJ63: 6046.942 | BK63: 70981.588 | BL63: 2034.8357 | BM63: 2791.345 | BN63: 291.55073 | BO63: 1593.2293 | BP63: 476.21441 | BQ63: 4.1172267 | BR63: 329.82623 | BS63: 22.379524 | BT63: 2327.781 | BU63: 4347.2818 | BV63: 1406.4368 | BW63: 31.592067 | BX63: 63172.438 | BY63: 8767.8177 | BZ63: 13820.458 | CA63: 5.4764229 | CB63: 32647.69 | CC63: 17272.985 | CD63: 90.654159 | CE63: 314349.91 | CF63: 1151.2586 | CG63: 20852.812 | CH63: 4911.6604 | CI63: 576.32703 | CJ63: 1928.438 | CK63: 516.2537 | CL63: 1062.9517 | CM63: 913.47059 | CN63: 715.17159 | CO63: 105225.83 | CP63: 0.018400076 | CQ63: 534.39844 | CR63: 272.13617 | CS63: 1895.3937 | CT63: 3697.3888 | CU63: 3437.2029 | CV63: 5752.1201 | CW63: 3429.9363 | CX63: 906.41244 | CY63: 876.01262 | CZ63: 6006.0113 | DA63: 1637.0102 | DB63: 3456.19 | DC63: 75.046811 | DD63: 69.648519 | DE63: 470.35923 | DF63: 1323.7862 | DG63: 2043.9272 | DH63: 1524.6505 | DI63: 192.75052 | DJ63: 1311.6432 | DK63: 0 | DL63: 18484.142 | DM63: 1409.1892 | DN63: 47664.793 | DO63: 0 | DQ63: =SUM(DH63:DJ63) -> 3029.0442 | DR63: =DQ63/SUM(DQ$58:DQ$111) -> 0.0045647642
A64: RoW | B64: Sector | C64: Processing of meat | D64: 47.138751 | E64: 661.82649 | F64: 2.2752484 | G64: 27.127185 | H64: 6.2930233 | I64: 24.834531 | J64: 4625.5163 | K64: 7829.0364 | L64: 4.7071007 | M64: 153.10932 | N64: 15.423465 | O64: 8.2851722 | P64: 4.8342366 | Q64: 17.697403 | R64: 46.079318 | S64: 36.71358 | T64: 372.22432 | U64: 122.66721 | V64: 163.38387 | W64: 51.990814 | X64: 10.486281 | Y64: 1.5378766 | Z64: 44.21035 | AA64: 13.542159 | AB64: 4.6572978 | AC64: 43.515355 | AD64: 17.607552 | AE64: 126.41187 | AF64: 50.271835 | AG64: 26.267113 | AH64: 25.3761 | AI64: 3.7077959 | AJ64: 8.5477445 | AK64: 11.705239 | AL64: 13.067222 | AM64: 64.585902 | AN64: 0.0085096326 | AO64: 6.8146137 | AP64: 15.078026 | AQ64: 110.91808 | AR64: 1866.4137 | AS64: 101.65468 | AT64: 179.13812 | AU64: 37.213922 | AV64: 12.469406 | AW64: 52.69488 | AX64: 94.881926 | AY64: 85.178175 | AZ64: 868.07454 | BA64: 4.6154515 | BB64: 2.0877157 | BC64: 1.879695 | BD64: 3.2387449 | BE64: 53.672333 | BF64: 2752.8259 | BG64: 18563.316 | BH64: 196.73697 | BI64: 3322.9526 | BJ64: 983.64102 | BK64: 1615.5086 | BL64: 131761.24 | BM64: 75242.364 | BN64: 233.11976 | BO64: 24024.123 | BP64: 150.93839 | BQ64: 2.8131092 | BR64: 83.161642 | BS64: 17.294508 | BT64: 786.11459 | BU64: 1822.4866 | BV64: 788.10903 | BW64: 24.891944 | BX64: 29540.324 | BY64: 520.67328 | BZ64: 185.0507 | CA64: 2.5370676 | CB64: 1196.2122 | CC64: 136.24624 | CD64: 18.398836 | CE64: 717.20262 | CF64: 15.436877 | CG64: 11228.898 | CH64: 2856.8524 | CI64: 556.37509 | CJ64: 1348.4851 | CK64: 285.97431 | CL64: 170.14598 | CM64: 152.0168 | CN64: 118.18693 | CO64: 1307.0946 | CP64: 0.01806731 | CQ64: 470.3956 | CR64: 195.42862 | CS64: 2228.921 | CT64: 90277.376 | CU64: 4357.7676 | CV64: 4079.8532 | CW64: 1741.2045 | CX64: 2238.6359 | CY64: 958.70314 | CZ64: 14998.255 | DA64: 6437.4072 | DB64: 30955.21 | DC64: 46.682011 | DD64: 29.566984 | DE64: 211.06038 | DF64: 139.90455 | DG64: 4216.1551 | DH64: 8628.2125 | DI64: 107.14125 | DJ64: 335.02608 | DK64: 0 | DL64: 765190.79 | DM64: 4182.6447 | DN64: 21391.893 | DO64: 0 | DQ64: =SUM(DH64:DJ64) -> 9070.3798 | DR64: =DQ64/SUM(DQ$58:DQ$111) -> 0.013669046
A65: RoW | B65: Sector | C65: Processing of other food&beverage | D65: 42.232823 | E65: 794.70687 | F65: 1.9924199 | G65: 13.477579 | H65: 3.6509028 | I65: 47.173895 | J65: 1582.3738 | K65: 3538.3984 | L65: 2.6601575 | M65: 107.30147 | N65: 10.741801 | O65: 5.8644993 | P65: 6.3211306 | Q65: 15.991759 | R65: 52.449494 | S65: 27.732497 | T65: 281.89045 | U65: 95.429525 | V65: 194.86737 | W65: 45.941458 | X65: 22.838745 | Y65: 1.549621 | Z65: 74.306251 | AA65: 37.230429 | AB65: 14.380402 | AC65: 49.480533 | AD65: 13.184034 | AE65: 111.73679 | AF65: 88.789262 | AG65: 15.182439 | AH65: 18.373355 | AI65: 3.165648 | AJ65: 8.0222957 | AK65: 7.5410478 | AL65: 9.5192922 | AM65: 101.02758 | AN65: 0.0099104384 | AO65: 12.025302 | AP65: 11.457452 | AQ65: 123.81029 | AR65: 1835.1817 | AS65: 86.809127 | AT65: 214.19025 | AU65: 24.907388 | AV65: 14.26138 | AW65: 30.988778 | AX65: 124.89266 | AY65: 96.96385 | AZ65: 492.27073 | BA65: 4.2598307 | BB65: 1.6250248 | BC65: 1.8192101 | BD65: 3.0132622 | BE65: 36.084239 | BF65: 1678.5867 | BG65: 119517.49 | BH65: 1062.0282 | BI65: 3522.2308 | BJ65: 1044.1263 | BK65: 3373.6505 | BL65: 31026.805 | BM65: 292576.42 | BN65: 371.1716 | BO65: 5595.1016 | BP65: 154.82906 | BQ65: 11.892159 | BR65: 77.017272 | BS65: 42.243625 | BT65: 2888.4519 | BU65: 656.94357 | BV65: 473.90021 | BW65: 43.322063 | BX65: 17031.022 | BY65: 9993.7526 | BZ65: 462.99833 | CA65: 6.0233248 | CB65: 2294.3262 | CC65: 386.98914 | CD65: 73.342801 | CE65: 2261.4856 | CF65: 28.416989 | CG65: 4175.4661 | CH65: 1460.112 | CI65: 206.81016 | CJ65: 637.9873 | CK65: 193.87265 | CL65: 156.08186 | CM65: 111.44942 | CN65: 70.244306 | CO65: 8291.8832 | CP65: 0.035052565 | CQ65: 396.01866 | CR65: 121.18827 | CS65: 2790.0414 | CT65: 135109.86 | CU65: 4903.3846 | CV65: 3355.9527 | CW65: 731.804 | CX65: 626.07944 | CY65: 2345.5336 | CZ65: 10009.561 | DA65: 3893.5272 | DB65: 26394.13 | DC65: 37.652344 | DD65: 24.748166 | DE65: 115.4545 | DF65: 213.0203 | DG65: 6171.3584 | DH65: 20162.387 | DI65: 72.074348 | DJ65: 365.46672 | DK65: 0 | DL65: 1217362.3 | DM65: 13514.191 | DN65: 31267.179 | DO65: 0 | DQ65: =SUM(DH65:DJ65) -> 20599.928 | DR65: =DQ65/SUM(DQ$58:DQ$111) -> 0.031044054
A66: RoW | B66: Sector | C66: Manufacture of tobacco products (16) | D66: 3.5445299 | E66: 0.97276214 | F66: 0.070394478 | G66: 0.13609261 | H66: 0.44817091 | I66: 0.43765909 | J66: 4.9089388 | K66: 6.0554289 | L66: 23.28206 | M66: 4.7137427 | N66: 0.57112784 | O66: 0.32100346 | P66: 0.23680812 | Q66: 0.56893938 | R66: 2.6130288 | S66: 1.5188621 | T66: 4.9700163 | U66: 2.5763807 | V66: 4.3817615 | W66: 1.9549633 | X66: 0.17917073 | Y66: 0.074480211 | Z66: 0.64848063 | AA66: 0.26632193 | AB66: 0.073508643 | AC66: 91.821944 | AD66: 9.6405257 | AE66: 18.818995 | AF66: 1.0837784 | AG66: 0.14032926 | AH66: 1.8473374 | AI66: 0.37685216 | AJ66: 0.36082718 | AK66: 1.1708365 | AL66: 0.42319557 | AM66: 14.37621 | AN66: 0.00083163962 | AO66: 0.43124307 | AP66: 0.093560628 | AQ66: 24.14127 | AR66: 69.961834 | AS66: 8.6438124 | AT66: 23.174491 | AU66: 1.4028825 | AV66: 2.136546 | AW66: 1.2053922 | AX66: 21.771002 | AY66: 1.1158116 | AZ66: 6.7836454 | BA66: 0.46774133 | BB66: 0.098933111 | BC66: 0.46611935 | BD66: 0.59279997 | BE66: 9.9310914 | BF66: 55.200183 | BG66: 14.347343 | BH66: 9.159687 | BI66: 4.9911947 | BJ66: 48.317642 | BK66: 41.505024 | BL66: 53.532196 | BM66: 56.070068 | BN66: 6118.0854 | BO66: 85.23936 | BP66: 6.3830481 | BQ66: 0.45491483 | BR66: 6.0143654 | BS66: 0.4583368 | BT66: 43.588722 | BU66: 32.183242 | BV66: 10.663162 | BW66: 0.79919431 | BX66: 513.27475 | BY66: 17.326715 | BZ66: 7.223494 | CA66: 0.083154827 | CB66: 17.03799 | CC66: 6.148574 | CD66: 0.097903052 | CE66: 3023.4812 | CF66: 10.688717 | CG66: 449.89303 | CH66: 21.938611 | CI66: 9.8639646 | CJ66: 56.733494 | CK66: 14.61978 | CL66: 9.312666 | CM66: 39.410082 | CN66: 4.4877135 | CO66: 151.607 | CP66: 0.00080522691 | CQ66: 13.550826 | CR66: 4.9965349 | CS66: 185.82955 | CT66: 814.78345 | CU66: 116.3923 | CV66: 568.08737 | CW66: 48.563732 | CX66: 69.669977 | CY66: 14.721087 | CZ66: 457.53834 | DA66: 31.597796 | DB66: 62.279351 | DC66: 3.9033468 | DD66: 1.3830287 | DE66: 7.3614591 | DF66: 16.750437 | DG66: 169.16401 | DH66: 760.14975 | DI66: 3.0884756 | DJ66: 24.450448 | DK66: 0 | DL66: 134348.99 | DM66: 25.40735 | DN66: 1357.6348 | DO66: 0 | DQ66: =SUM(DH66:DJ66) -> 787.68867 | DR66: =DQ66/SUM(DQ$58:DQ$111) -> 0.0011870454
A67: RoW | B67: Sector | C67: Manufacture of textiles | D67: 109.92019 | E67: 77.225567 | F67: 28.366703 | G67: 53.852682 | H67: 22.703705 | I67: 21.710707 | J67: 48.02487 | K67: 181.63568 | L67: 24.073416 | M67: 13494.622 | N67: 48.410409 | O67: 32.840741 | P67: 15.694414 | Q67: 56.206748 | R67: 194.43074 | S67: 26.343095 | T67: 135.074 | U67: 55.456715 | V67: 299.01187 | W67: 636.93163 | X67: 33.475508 | Y67: 12.65012 | Z67: 46.107485 | AA67: 25.29682 | AB67: 5.940101 | AC67: 82.732988 | AD67: 35.856 | AE67: 1899.157 | AF67: 653.20659 | AG67: 9.7918665 | AH67: 33.043327 | AI67: 2.6954188 | AJ67: 15.434759 | AK67: 11.741749 | AL67: 16.384728 | AM67: 670.59229 | AN67: 0.6857873 | AO67: 40.797943 | AP67: 16.23934 | AQ67: 253.58585 | AR67: 424.70571 | AS67: 216.1448 | AT67: 416.51302 | AU67: 30.197745 | AV67: 60.109001 | AW67: 43.415176 | AX67: 385.77466 | AY67: 66.893066 | AZ67: 641.09165 | BA67: 29.894514 | BB67: 14.468348 | BC67: 8.8180717 | BD67: 22.194938 | BE67: 201.07217 | BF67: 2997.534 | BG67: 824.93322 | BH67: 337.0846 | BI67: 1647.3035 | BJ67: 2315.2035 | BK67: 2277.214 | BL67: 750.95778 | BM67: 2850.6094 | BN67: 668.22897 | BO67: 575936.63 | BP67: 1362.7245 | BQ67: 6.7576448 | BR67: 94.152191 | BS67: 9.9961261 | BT67: 14347.487 | BU67: 595.78918 | BV67: 325.25091 | BW67: 6.9553393 | BX67: 20891.597 | BY67: 17964.595 | BZ67: 1369.7471 | CA67: 17.627254 | CB67: 2245.8286 | CC67: 386.51687 | CD67: 3.0733478 | CE67: 3866.3187 | CF67: 25.052845 | CG67: 39472.809 | CH67: 32847.167 | CI67: 417.43918 | CJ67: 1714.6794 | CK67: 716.09235 | CL67: 315.81963 | CM67: 451.51689 | CN67: 219.62963 | CO67: 19020.903 | CP67: 0.15456555 | CQ67: 598.68341 | CR67: 130.64595 | CS67: 3947.1102 | CT67: 8120.7446 | CU67: 8686.9445 | CV67: 14123.075 | CW67: 3916.3635 | CX67: 1523.9837 | CY67: 11630.448 | CZ67: 16762.286 | DA67: 2173.063 | DB67: 17139.871 | DC67: 297.3953 | DD67: 128.16175 | DE67: 982.66621 | DF67: 722.48327 | DG67: 9594.2326 | DH67: 60382.629 | DI67: 88.959889 | DJ67: 991.21781 | DK67: 0 | DL67: 654051.11 | DM67: 2458.9157 | DN67: 37154.3 | DO67: 0 | DQ67: =SUM(DH67:DJ67) -> 61462.806 | DR67: =DQ67/SUM(DQ$58:DQ$111) -> 0.092624338
