Workbook

Sheet global.pars
A1: label | B1: name | C1: value
A2: nPeriods | B2: Time Span of the Simulation | C2: 100
A3: max.iterations | B3: Maximum Number of Algorithm Iterations | C3: 100
A4: tolerance | B4: Tolerance of Algorithm | C4: 1e-06
A5: consistency.threshold | B5: SFC Consistency Threshold | C5: 0.01
A6: shock | B6: Shock Number | C6: 0
A7: t.shock | B7: Time of Shock | C7: 70
A8: rho | B8: Shock Parameter | C8: 0.25
A9: sigma_en | B9: Conversion Rate of Energy Resources into Reserves | C9: 0.003
A10: sigma_mat | B10: Conversion Rate of Matter Resources into Reserves | C10: 0.0005
A11: tcre | B11: Transient Climate Response to Cumulative Carbon Emissions | C11: 0.0001
A12: par_xr | B12: Sensitivity of Z1 Exchange Rate to CAB/YN | C12: 0.15
A13: fnc | B13: Non-CO2 Fraction of Total Anthropocentric Forcing | C13: 0.5

Sheet aggregate.pars
A1: label | B1: name | C1: industry | D1: type | E1: Z1 | F1: Z2
A2: alpha1 | B2: Propensity to Consume out of Wages | C2: aggregate | D2: households | E2: 0.85436972 | F2: 0.85436972
A3: alpha2 | B3: Propensity to Consume out of Profits | C3: aggregate | D3: households | E3: 0.4190559 | F3: 0.4190559
A4: alpha3 | B4: Propensity to Consume out of Wealth | C4: aggregate | D4: households | E4: 0.099375767 | F4: 0.099375767
A5: beta_e | B5: CO2 Intensity | C5: aggregate | D5: ecological | E5: 1 | F5: 1
A6: beta10 | B6: Initial Consumption Share Parameter (Disabled) | C6: aggregate | D6: households | E6: 0.29 | F6: 0.27
A7: beta20 | B7: Initial Consumption Share Parameter (Disabled) | C7: aggregate | D7: households | E7: 0.03 | F7: 0.05
A8: beta30 | B8: Initial Consumption Share Parameter (Disabled) | C8: aggregate | D8: households | E8: 0.68 | F8: 0.68
A9: beta31 | B9: Initial Consumption Share Parameter (Disabled) | C9: aggregate | D9: households | E9: 0 | F9: 0
A10: beta32 | B10: Initial Consumption Share Parameter (Disabled) | C10: aggregate | D10: households | E10: 0 | F10: 0
A11: ce | B11: Circular economy (0 = off; 1 = on) | C11: aggregate | D11: ecological | E11: 0 | F11: 0
A12: delta_g | B12: Government Depreciation Rate of Fixed Capital | C12: aggregate | D12: investment | E12: 0 | F12: 0
A13: g_g | B13: Growth Rate of Government Spending | C13: aggregate | D13: govt.central.bank | E13: 0 | F13: 0
... A58: rep | B58: Repayment Rate of Personal Loans | C58: aggregate | D58: ecological | E58: 0.001 | F58: 0.001

Sheet global.vars
A1: label | B1: variable | C1: name | D1: area | E1: industry | F1: t1
A2: conv_en | B2: conv_en | C2: Global Energy Resources Converted into Reserves | D2: global | E2: aggregate | F2: 0
A3: conv_mat | B3: conv_mat | C3: Global Material Resources Converted into Reserves | D3: global | E3: aggregate | F3: 0
A4: ken | B4: ken | C4: Global Stock of Energy Reserves | D4: global | E4: aggregate | F4: 37000
A5: kmat | B5: kmat | C5: Global Stock of Material Reserves | D5: global | E5: aggregate | F5: 10000000
A6: res_en | B6: res_en | C6: Global Stock of Energy Resources | D6: global | E6: aggregate | F6: 542000
A7: res_mat | B7: res_mat | C7: Global Stock of Material Resources | D7: global | E7: aggregate | F7: 390000000
A8: temp | B8: temp | C8: Atmospheric Temperature | D8: global | E8: aggregate | F8: 0

Sheet aggregate.vars
A1: variable | B1: name | C1: industry | D1: dynamic | E1: type | F1: Z1 | G1: Z2
A2: a_d | B2: Demand for Advances | C2: aggregate | D2: endogenous | E2: commercial.banks | F2: 0 | G2: 0
A3: a_s | B3: Central Bank Advances: Supply | C3: aggregate | D3: endogenous | E3: govt.central.bank | F3: 0 | G3: 0
A4: af | B4: Amortization Funds | C4: aggregate | D4: endogenous | E4: investment | F4: 0 | G4: 0
A5: b_b | B5: Holdings of Bills | C5: aggregate | D5: endogenous | E5: commercial.banks | F5: 0 | G5: 0
A6: b_cb | B6: Central Bank Holdings of Domestic Bills | C6: aggregate | D6: endogenous | E6: govt.central.bank | F6: 0 | G6: 0
A7: b_cb_d_Z2 | B7: Z2 Bills held by Z1 Central Bank | C7: aggregate | D7: endogenous | E7: govt.central.bank | F7: 0 | G7: 0
A8: b_cb_s_Z2 | B8: Supply of Z2 bills to Z1 Central Bank | C8: aggregate | D8: endogenous | E8: govt.central.bank | F8: 0 | G8: 0
A9: b_h_Z1 | B9: Private Demand for Z1 Bills | C9: aggregate | D9: endogenous | E9: portfolio.choices | F9: 0 | G9: 0
A10: b_h_Z2 | B10: Private Demand for Z2 Bills | C10: aggregate | D10: endogenous | E10: portfolio.choices | F10: 0 | G10: 0
A11: b_s | B11: Supply of Government Bills (Government Debt) | C11: aggregate | D11: endogenous | E11: govt.central.bank | F11: 0 | G11: 0
A12: b_s_Z1 | B12: Supply of Z1 Bills to Households | C12: aggregate | D12: endogenous | E12: govt.central.bank | F12: 0 | G12: 0
A13: b_s_Z2 | B13: Supply of Z2 Bills to Households | C13: aggregate | D13: endogenous | E13: govt.central.bank | F13: 0 | G13: 0
... A70: nex | B70: Nominal Exports | C70: aggregate | D70: endogenous | E70: balance.of.payments | F70: 0 | G70: 0
A71: nh | B71: Domestic Employment | C71: aggregate | D71: endogenous | F71: 0 | G71: 0
A72: nimp | B72: Nominal Imports | C72: aggregate | D72: endogenous | E72: balance.of.payments | F72: 0 | G72: 0
A73: or | B73: Quantity of Reserves | C73: aggregate | D73: endogenous | E73: govt.central.bank | F73: 0 | G73: 0
A74: p_or | B74: Price of Reserves | C74: aggregate | D74: endogenous | E74: govt.central.bank | F74: 1 | G74: 1
A75: pa | B75: Average Price of Domestic Consumption | C75: aggregate | D75: endogenous | E75: prices | F75: 0 | G75: 0
A76: pg | B76: Average Price of Government Spending | C76: aggregate | D76: endogenous | E76: prices | F76: 1 | G76: 1
A77: pid | B77: Average Price of Investment | C77: aggregate | D77: endogenous | E77: prices | F77: 1 | G77: 1
A78: pid_g | B78: Average Price of Government Investment | C78: aggregate | D78: endogenous | E78: prices | F78: 1 | G78: 1
A79: pim | B79: Average Price of Imports | C79: aggregate | D79: endogenous | E79: prices | F79: 1 | G79: 1
A80: r_e | B80: Return Rate on Shares | C80: aggregate | D80: endogenous | E80: investment | F80: 0 | G80: 0
A81: r_star | B81: Policy Rate | C81: aggregate | D81: endogenous | E81: portfolio.choices | F81: 0.012115993 | G81: 0.010294681
A82: rb | B82: Interest Rate on Bills | C82: aggregate | D82: endogenous | E82: portfolio.choices | F82: 0.03 | G82: 0.03
A83: rec | B83: Recycled Matter | C83: aggregate | D83: endogenous | E83: ecological | F83: 0 | G83: 0
... A114: yn | B114: Net Income / Value Added | C114: aggregate | D114: endogenous | E114: production | F114: 0 | G114: 0

Sheet industry.vars
A1: variable | B1: name | C1: area | D1: dynamic | E1: type | F1: 1 | G1: 2 | H1: 3 | I1: 4 | J1: 5 | K1: 6 | L1: 7 | M1: 8 | N1: 9 | O1: 10 | P1: 11 | Q1: 12 | R1: 13 | S1: 14 | T1: 15 | U1: 16 | V1: 17 | W1: 18 | X1: 19 | Y1: 20 | Z1: 21 | AA1: 22 | AB1: 23 | AC1: 24 | AD1: 25 | AE1: 26 | AF1: 27 | AG1: 28 | AH1: 29 | AI1: 30 | AJ1: 31 | AK1: 32 | AL1: 33 | AM1: 34 | AN1: 35 | AO1: 36 | AP1: 37 | AQ1: 38 | AR1: 39 | AS1: 40 | AT1: 41 | AU1: 42 | AV1: 43 | AW1: 44 | AX1: 45 | AY1: 46 | AZ1: 47 | BA1: 48 | BB1: 49 | BC1: 50 | BD1: 51 | BE1: 52 | BF1: 53 | BG1: 54
A2: beta_Z1 | B2: Z1 Sector Share of Z1 Household Consumption | C2: Z1 | D2: exogenous | F2: 0.013844114 | G2: 0.0049606998 | H2: 0.0010452624 | I2: 0.0014849907 | J2: 0.00083468405 | K2: 0.00025337025 | L2: 0.037024813 | M2: 0.048241995 | N2: 0.0020218725 | O2: 0.021601267 | P2: 0.0016648753 | Q2: 0.00059674027 | R2: 4.5200922e-05 | S2: 7.7440804e-05 | T2: 0.014650851 | U2: 0.019899025 | V2: 0.0017777596 | W2: 0.00042783189 | X2: 0.0020109559 | Y2: 0.0045585608 | Z2: 3.110773e-05 | AA2: 1.0918521e-05 | AB2: 0.0028902128 | AC2: 0.00016652631 | AD2: 3.6390004e-05 | AE2: 0.00056998673 | AF2: 0.00025391127 | AG2: 0.039918567 | AH2: 0.0098837912 | AI2: 0.0003091554 | AJ2: 0.010761352 | AK2: 0.0019968031 | AL2: 0.014069233 | AM2: 0.0027709507 | AN2: 0.006772066 | AO2: 0.0063176031 | AP2: 5.4340816e-06 | AQ2: 0.029404956 | AR2: 0.0018293271 | AS2: 0.03027168 | AT2: 0.11323634 | AU2: 0.066958243 | AV2: 0.10050478 | AW2: 0.17034441 | AX2: 0.0033514647 | AY2: 0.0028243816 | AZ2: 0.0071925149 | BA2: 0.019960592 | BB2: 0.056676196 | BC2: 0.0041821159 | BD2: 0.0014236024 | BE2: 0.00077081054 | BF2: 0.0013365905 | BG2: 0.048947737
A3: beta_Z1 | B3: Z2 Sector Share of Z1 Household Consumption | C3: Z2 | D3: exogenous | F3: 0.0053695873 | G3: 0.00035778581 | H3: 3.6827721e-05 | I3: 0.0005020375 | J3: 0.00038589593 | K3: 0.00024343078 | L3: 0.0013776092 | M3: 0.0032191939 | N3: 0.00012136804 | O3: 0.0096408917 | P3: 0.00017105312 | Q3: 9.8332967e-06 | R3: 3.6834134e-06 | S3: 1.0205041e-05 | T3: 0.00070997941 | U3: 0.0035727161 | V3: 7.0977218e-05 | W3: 1.083514e-05 | X3: 0.00050027569 | Y3: 0.001303104 | Z3: 4.2597882e-06 | AA3: 3.0147659e-07 | AB3: 0.0005569324 | AC3: 1.0350695e-05 | AD3: 4.3408316e-07 | AE3: 5.8572955e-05 | AF3: 3.6120274e-06 | AG3: 0.0099850309 | AH3: 0.0024643854 | AI3: 7.5894913e-06 | AJ3: 1.6075583e-05 | AK3: 6.2559554e-06 | AL3: 1.2678854e-05 | AM3: 3.8120093e-06 | AN3: 4.6149339e-06 | AO3: 5.2697978e-05 | AP3: 9.56364e-09 | AQ3: 7.7460687e-05 | AR3: 7.0970321e-06 | AS3: 0.00073965363 | AT3: 0.011172376 | AU3: 0.0080519144 | AV3: 0.0027149424 | AW3: 0.0020810878 | AX3: 3.0147695e-05 | AY3: 0.00022582039 | AZ3: 8.0710359e-05 | BA3: 0.00020885709 | BB3: 0.00045204803 | BC3: 2.0205713e-05 | BD3: 1.7691005e-05 | BE3: 1.7814136e-05 | BF3: 6.4196218e-05 | BG3: 0.00023101765
A4: beta_Z2 | B4: Z1 Sector Share of Z2 Household Consumption | C4: Z1 | D4: exogenous | F4: 0.00047120683 | G4: 3.123948e-05 | H4: 1.3568424e-05 | I4: 1.9011147e-05 | J4: 5.9700871e-06 | K4: 1.0062816e-05 | L4: 0.0010405254 | M4: 0.0017562226 | N4: 0.00016543093 | O4: 0.0014625813 | P4: 5.4789564e-05 | Q4: 1.446995e-05 | R4: 1.2639988e-06 | S4: 1.620305e-06 | T4: 0.00048828426 | U4: 0.0010145107 | V4: 3.9426039e-05 | W4: 1.3714443e-05 | X4: 0.001144728 | Y4: 0.00031266761 | Z4: 1.5888578e-05 | AA4: 6.4672171e-06 | AB4: 0.00014399197 | AC4: 8.6948503e-06 | AD4: 1.4264186e-06 | AE4: 2.6854822e-05 | AF4: 1.3299921e-05 | AG4: 0.0052496145 | AH4: 0.00069209807 | AI4: 3.8554875e-06 | AJ4: 5.6719521e-06 | AK4: 8.4277845e-07 | AL4: 6.011987e-06 | AM4: 1.3801019e-06 | AN4: 5.6765911e-06 | AO4: 4.110481e-05 | AP4: 6.4483852e-08 | AQ4: 9.8499665e-05 | AR4: 3.738902e-06 | AS4: 0.00087320199 | AT4: 0.0042842419 | AU4: 0.0017235829 | AV4: 0.0014917297 | AW4: 0.00060799328 | AX4: 2.4411659e-05 | AY4: 4.6879374e-05 | AZ4: 0.00015323595 | BA4: 8.9137497e-05 | BB4: 0.00014701033 | BC4: 1.8687359e-05 | BD4: 8.9404415e-06 | BE4: 6.3541789e-06 | BF4: 1.2011188e-05 | BG4: 0.0016965702
A5: beta_Z2 | B5: Z2 Sector Share of Z2 Household Consumption | C5: Z2 | D5: exogenous | F5: 0.028366619 | G5: 0.0084227703 | H5: 0.0017863055 | I5: 0.0024229466 | J5: 0.0034092804 | K5: 0.00077968937 | L5: 0.032276917 | M5: 0.051350201 | N5: 0.0056670455 | O5: 0.027588875 | P5: 0.00071279641 | Q5: 3.7776582e-05 | R5: 3.7951279e-05 | S5: 9.7647898e-06 | T5: 0.011333779 | U5: 0.01957389 | V5: 0.00016564471 | W5: 9.5928798e-06 | X5: 0.014116134 | Y5: 0.0037441534 | Z5: 0.00046260256 | AA5: 1.9921612e-06 | AB5: 0.0013391091 | AC5: 7.1639826e-05 | AD5: 1.2322953e-06 | AE5: 0.00048728948 | AF5: 1.6042025e-05 | AG5: 0.044449688 | AH5: 0.011366164 | AI5: 6.1120441e-05 | AJ5: 0.0086919324 | AK5: 0.0014362438 | AL5: 0.0072799921 | AM5: 0.0043581816 | AN5: 0.0036062723 | AO5: 0.0021816875 | AP5: 2.0481518e-07 | AQ5: 0.021970661 | AR5: 0.00036796489 | AS5: 0.031697264 | AT5: 0.10728806 | AU5: 0.050279189 | AV5: 0.10394181 | AW5: 0.13208963 | AX5: 0.0087461406 | AY5: 0.0023970646 | AZ5: 0.052331505 | BA5: 0.02976693 | BB5: 0.08626271 | BC5: 0.00075366174 | BD5: 0.00037663915 | BE5: 0.0029711633 | BF5: 0.003776784 | BG5: 0.041788833
A6: d | B6: Final Demand on Z1 Industry | C6: Z1 | D6: endogenous | E6: production | F6: 0 | G6: 0 | H6: 0 | I6: 0 | J6: 0 | K6: 0 | L6: 0 | M6: 0 | N6: 0 | O6: 0 | P6: 0 | Q6: 0 | R6: 0 | S6: 0 | T6: 0 | U6: 0 | V6: 0 | W6: 0 | X6: 0 | Y6: 0 | Z6: 0 | AA6: 0 | AB6: 0 | AC6: 0 | AD6: 0 | AE6: 0 | AF6: 0 | AG6: 0 | AH6: 0 | AI6: 0 | AJ6: 0 | AK6: 0 | AL6: 0 | AM6: 0 | AN6: 0 | AO6: 0 | AP6: 0 | AQ6: 0 | AR6: 0 | AS6: 0 | AT6: 0 | AU6: 0 | AV6: 0 | AW6: 0 | AX6: 0 | AY6: 0 | AZ6: 0 | BA6: 0 | BB6: 0 | BC6: 0 | BD6: 0 | BE6: 0 | BF6: 0 | BG6: 0
A7: d | B7: Final Demand on Z2 Industry | C7: Z2 | D7: endogenous | E7: production | F7: 0 | G7: 0 | H7: 0 | I7: 0 | J7: 0 | K7: 0 | L7: 0 | M7: 0 | N7: 0 | O7: 0 | P7: 0 | Q7: 0 | R7: 0 | S7: 0 | T7: 0 | U7: 0 | V7: 0 | W7: 0 | X7: 0 | Y7: 0 | Z7: 0 | AA7: 0 | AB7: 0 | AC7: 0 | AD7: 0 | AE7: 0 | AF7: 0 | AG7: 0 | AH7: 0 | AI7: 0 | AJ7: 0 | AK7: 0 | AL7: 0 | AM7: 0 | AN7: 0 | AO7: 0 | AP7: 0 | AQ7: 0 | AR7: 0 | AS7: 0 | AT7: 0 | AU7: 0 | AV7: 0 | AW7: 0 | AX7: 0 | AY7: 0 | AZ7: 0 | BA7: 0 | BB7: 0 | BC7: 0 | BD7: 0 | BE7: 0 | BF7: 0 | BG7: 0
A8: dc | B8: Durable Consumption Goods | C8: Z1 | D8: endogenous | E8: ecological | F8: 0 | G8: 0 | H8: 0 | I8: 0 | J8: 0 | K8: 0 | L8: 0 | M8: 0 | N8: 0 | O8: 0 | P8: 0 | Q8: 0 | R8: 0 | S8: 0 | T8: 0 | U8: 0 | V8: 0 | W8: 0 | X8: 0 | Y8: 0 | Z8: 0 | AA8: 0 | AB8: 0 | AC8: 0 | AD8: 0 | AE8: 0 | AF8: 0 | AG8: 0 | AH8: 0 | AI8: 0 | AJ8: 0 | AK8: 0 | AL8: 0 | AM8: 0 | AN8: 0 | AO8: 0 | AP8: 0 | AQ8: 0 | AR8: 0 | AS8: 0 | AT8: 0 | AU8: 0 | AV8: 0 | AW8: 0 | AX8: 0 | AY8: 0 | AZ8: 0 | BA8: 0 | BB8: 0 | BC8: 0 | BD8: 0 | BE8: 0 | BF8: 0 | BG8: 0
A9: dc | B9: Durable Consumption Goods | C9: Z2 | D9: endogenous | E9: ecological | F9: 0 | G9: 0 | H9: 0 | I9: 0 | J9: 0 | K9: 0 | L9: 0 | M9: 0 | N9: 0 | O9: 0 | P9: 0 | Q9: 0 | R9: 0 | S9: 0 | T9: 0 | U9: 0 | V9: 0 | W9: 0 | X9: 0 | Y9: 0 | Z9: 0 | AA9: 0 | AB9: 0 | AC9: 0 | AD9: 0 | AE9: 0 | AF9: 0 | AG9: 0 | AH9: 0 | AI9: 0 | AJ9: 0 | AK9: 0 | AL9: 0 | AM9: 0 | AN9: 0 | AO9: 0 | AP9: 0 | AQ9: 0 | AR9: 0 | AS9: 0 | AT9: 0 | AU9: 0 | AV9: 0 | AW9: 0 | AX9: 0 | AY9: 0 | AZ9: 0 | BA9: 0 | BB9: 0 | BC9: 0 | BD9: 0 | BE9: 0 | BF9: 0 | BG9: 0
A10: emis_j | B10: Annual CO2 Emissions | C10: Z1 | D10: endogenous | E10: ecological | F10: 0 | G10: 0 | H10: 0 | I10: 0 | J10: 0 | K10: 0 | L10: 0 | M10: 0 | N10: 0 | O10: 0 | P10: 0 | Q10: 0 | R10: 0 | S10: 0 | T10: 0 | U10: 0 | V10: 0 | W10: 0 | X10: 0 | Y10: 0 | Z10: 0 | AA10: 0 | AB10: 0 | AC10: 0 | AD10: 0 | AE10: 0 | AF10: 0 | AG10: 0 | AH10: 0 | AI10: 0 | AJ10: 0 | AK10: 0 | AL10: 0 | AM10: 0 | AN10: 0 | AO10: 0 | AP10: 0 | AQ10: 0 | AR10: 0 | AS10: 0 | AT10: 0 | AU10: 0 | AV10: 0 | AW10: 0 | AX10: 0 | AY10: 0 | AZ10: 0 | BA10: 0 | BB10: 0 | BC10: 0 | BD10: 0 | BE10: 0 | BF10: 0 | BG10: 0
A11: emis_j | B11: Annual CO2 Emissions | C11: Z2 | D11: endogenous | E11: ecological | F11: 0 | G11: 0 | H11: 0 | I11: 0 | J11: 0 | K11: 0 | L11: 0 | M11: 0 | N11: 0 | O11: 0 | P11: 0 | Q11: 0 | R11: 0 | S11: 0 | T11: 0 | U11: 0 | V11: 0 | W11: 0 | X11: 0 | Y11: 0 | Z11: 0 | AA11: 0 | AB11: 0 | AC11: 0 | AD11: 0 | AE11: 0 | AF11: 0 | AG11: 0 | AH11: 0 | AI11: 0 | AJ11: 0 | AK11: 0 | AL11: 0 | AM11: 0 | AN11: 0 | AO11: 0 | AP11: 0 | AQ11: 0 | AR11: 0 | AS11: 0 | AT11: 0 | AU11: 0 | AV11: 0 | AW11: 0 | AX11: 0 | AY11: 0 | AZ11: 0 | BA11: 0 | BB11: 0 | BC11: 0 | BD11: 0 | BE11: 0 | BF11: 0 | BG11: 0
A12: eps | B12: Carbon Intensity | C12: Z1 | D12: exogenous | E12: ecological | F12: 568.79952 | G12: 2241.1199 | H12: 200.16538 | I12: 278.73907 | J12: 2570.5896 | K12: 954.53386 | L12: 47.828932 | M12: 58.857689 | N12: 219.03719 | O12: 30.846739 | P12: 55.615115 | Q12: 86.940062 | R12: 298.92455 | S12: 71.864394 | T12: 67.413795 | U12: 410.8344 | V12: 152.1438 | W12: 146.00559 | X12: 285.49063 | Y12: 14.707036 | Z12: 459.48734 | AA12: 600.73566 | AB12: 634.9624 | AC12: 1254.7799 | AD12: 1278.0706 | AE12: 276.54822 | AF12: 429.88479 | AG12: 22.347235 | AH12: 81.301967 | AI12: 1018.9513 | AJ12: 2770.8566 | AK12: 842.56443 | AL12: 95.842341 | AM12: 383.01701 | AN12: 4653.5563 | AO12: 19.816537 | AP12: 4577.1976 | AQ12: 36.193573 | AR12: 59.354604 | AS12: 20.055238 | AT12: 16.59838 | AU12: 320.70869 | AV12: 19.696819 | AW12: 10.775117 | AX12: 23.40054 | AY12: 19.552502 | AZ12: 18.077121 | BA12: 14.810873 | BB12: 15.653615 | BC12: 202.80412 | BD12: 224.77065 | BE12: 1597.0383 | BF12: 5723.6428 | BG12: 18.776869
A13: eps | B13: Carbon Intensity | C13: Z2 | D13: exogenous | E13: ecological | F13: 1072.9098 | G13: 4122.2841 | H13: 147.10102 | I13: 60.623675 | J13: 1676.5572 | K13: 587.05198 | L13: 116.44834 | M13: 71.177611 | N13: 884.45546 | O13: 203.65715 | P13: 469.39627 | Q13: 840.20978 | R13: 394.59968 | S13: 1054.7892 | T13: 190.94983 | U13: 497.86119 | V13: 167.99975 | W13: 7062.9215 | X13: 447.13886 | Y13: 64.927114 | Z13: 307.98563 | AA13: 10228.114 | AB13: 1096.1289 | AC13: 8707.6964 | AD13: 22089.369 | AE13: 730.71414 | AF13: 5690.0866 | AG13: 59.14027 | AH13: 219.00006 | AI13: 1450.4533 | AJ13: 10361.036 | AK13: 937.58928 | AL13: 67.065844 | AM13: 1558.6062 | AN13: 7151.673 | AO13: 34.284489 | AP13: 105260.26 | AQ13: 15.429905 | AR13: 814.27989 | AS13: 31.367964 | AT13: 24.125571 | AU13: 440.55788 | AV13: 21.435832 | AW13: 15.088698 | AX13: 26.277851 | AY13: 54.716356 | AZ13: 32.878902 | BA13: 24.946338 | BB13: 32.361604 | BC13: 974.99487 | BD13: 432.34665 | BE13: 3063.0319 | BF13: 5054.1305 | BG13: 48.2241
A14: eps_en | B14: Energy Intensity of Output | C14: Z1 | D14: exogenous | E14: ecological | F14: 1.0795189 | G14: 0.84171279 | H14: 0.69838011 | I14: 11.430738 | J14: 2.5644837 | K14: 0.11007846 | L14: 202.99842 | M14: 429.43045 | N14: 44975.353 | O14: 2363.6782 | P14: 135.37085 | Q14: 155.17142 | R14: 1495.0467 | S14: 6380.2343 | T14: 1754.7778 | U14: 19991.793 | V14: 124.98121 | W14: 55.192562 | X14: 164.42115 | Y14: 460.13429 | Z14: 6.6541198 | AA14: 8.3022567 | AB14: 9.5655522 | AC14: 7.1024357 | AD14: 11.419636 | AE14: 81.679797 | AF14: 145.92433 | AG14: 114.71345 | AH14: 139.59823 | AI14: 98.137059 | AJ14: 497.60511 | AK14: 912.87867 | AL14: 9.5012852 | AM14: 74.006497 | AN14: 163.8929 | AO14: 6.2210555 | AP14: 648.85456 | AQ14: 6404.9826 | AR14: 2907.8329 | AS14: 9.1647787 | AT14: 914.48335 | AU14: 212.89513 | AV14: 501.06924 | AW14: 460.76816 | AX14: 176.41677 | AY14: 385.75869 | AZ14: 161.61231 | BA14: 4218.749 | BB14: 16667.454 | BC14: 854.0657 | BD14: 63.331661 | BE14: 47.38698 | BF14: 21.053192 | BG14: 1064.8622
A15: eps_en | B15: Energy Intensity of Output | C15: Z2 | D15: exogenous | E15: ecological | F15: 0.86994505 | G15: 0.29310794 | H15: 0.85378678 | I15: 2.86275 | J15: 2.0714802 | K15: 0.15796793 | L15: 61.547055 | M15: 23.188168 | N15: 25251.86 | O15: 1395.6408 | P15: 601.54499 | Q15: 483.45532 | R15: 508.21028 | S15: 32657149 | T15: 1318.2699 | U15: 12957.249 | V15: 4222.2463 | W15: 735690.81 | X15: 433.51415 | Y15: 791.56448 | Z15: 229.27607 | AA15: 1729.687 | AB15: 277.26268 | AC15: 205.20368 | AD15: 4633.4398 | AE15: 973.8169 | AF15: 2189.0839 | AG15: 612.1505 | AH15: 762.78664 | AI15: 642.31257 | AJ15: 10795.767 | AK15: 1222.5407 | AL15: 77.413452 | AM15: 3655.5196 | AN15: 6313.6285 | AO15: 42.434609 | AP15: 1086766.1 | AQ15: 32.761556 | AR15: 84.06961 | AS15: 26.992782 | AT15: 582.5352 | AU15: 412.17135 | AV15: 3673.2441 | AW15: 14532.546 | AX15: 713.66222 | AY15: 319.11877 | AZ15: 446.907 | BA15: 1605.6513 | BB15: 3950.613 | BC15: 4480.246 | BD15: 154.80614 | BE15: 11627.565 | BF15: 80.50502 | BG15: 467.92584
A16: eta | B16: Share of Imports | C16: Z1 | D16: exogenous | F16: 0.053361169 | G16: 0.0040128461 | H16: 0.00054121911 | I16: 0.0047938579 | J16: 0.036005861 | K16: 0.0045647642 | L16: 0.013669046 | M16: 0.031044054 | N16: 0.0011870454 | O16: 0.092624338 | P16: 0.0022825122 | Q16: 0.00012170914 | R16: 0.0003593964 | S16: 0.00019461773 | T16: 0.0075850781 | U16: 0.040618313 | V16: 0.0078289955 | W16: 0.00044133574 | X16: 0.01654476 | Y16: 0.01372378 | Z16: 0.00018136398 | AA16: 9.7300528e-06 | AB16: 0.005591619 | AC16: 0.0001796589 | AD16: 9.4323047e-06 | AE16: 0.0032469058 | AF16: 0.00015764682 | AG16: 0.30873968 | AH16: 0.030705391 | AI16: 0.00023008088 | AJ16: 0.0003310145 | AK16: 0.00011100929 | AL16: 0.00032193851 | AM16: 7.6240896e-05 | AN16: 0.00018960098 | AO16: 0.011737443 | AP16: 2.2686155e-06 | AQ16: 0.0014621435 | AR16: 0.00012939681 | AS16: 0.010631591 | AT16: 0.10722867 | AU16: 0.081741593 | AV16: 0.049787117 | AW16: 0.01986798 | AX16: 0.00031384252 | AY16: 0.006730771 | AZ16: 0.0090160749 | BA16: 0.0058968002 | BB16: 0.0097742202 | BC16: 0.00024748371 | BD16: 0.000224586 | BE16: 0.00022684537 | BF16: 0.00087413577 | BG16: 0.0025210196
A17: eta | B17: Share of Imports | C17: Z2 | D17: exogenous | F17: 0.011073165 | G17: 0.0013767005 | H17: 0.0003512261 | I17: 0.00044243217 | J17: 0.00023002764 | K17: 0.00050166593 | L17: 0.02420308 | M17: 0.040847141 | N17: 0.0038261524 | O17: 0.034878401 | P17: 0.0022715188 | Q17: 0.0005760218 | R17: 6.9257408e-05 | S17: 7.0822798e-05 | T17: 0.012010442 | U17: 0.025221024 | V17: 0.0020280689 | W17: 0.00061880509 | X17: 0.0271086 | Y17: 0.0087650085 | Z17: 0.00043640973 | AA17: 0.00017366827 | AB17: 0.0034816995 | AC17: 0.00033827535 | AD17: 6.2885851e-05 | AE17: 0.0025079803 | AF17: 0.0010465337 | AG17: 0.44013502 | AH17: 0.02120673 | AI17: 0.00017119736 | AJ17: 0.00039348645 | AK17: 6.0468557e-05 | AL17: 0.00046399771 | AM17: 0.00013074707 | AN17: 0.00030476449 | AO17: 0.015842434 | AP17: 2.6720637e-05 | AQ17: 0.0033082327 | AR17: 0.00012223699 | AS17: 0.027802529 | AT17: 0.099807095 | AU17: 0.042793104 | AV17: 0.062712345 | AW17: 0.014896235 | AX17: 0.00064366492 | AY17: 0.0018335276 | AZ17: 0.01305901 | BA17: 0.0037024414 | BB17: 0.0053957368 | BC17: 0.00053709828 | BD17: 0.00036355909 | BE17: 0.00018788474 | BF17: 0.00033648931 | BG17: 0.039246227
A18: eta_en | B18: Shares of Renewable Energy in Total Energy | C18: Z1 | D18: exogenous | F18: 0.14 | G18: 0.14 | H18: 0.14 | I18: 0.14 | J18: 0.14 | K18: 0.14 | L18: 0.14 | M18: 0.14 | N18: 0.14 | O18: 0.14 | P18: 0.14 | Q18: 0.14 | R18: 0.14 | S18: 0.14 | T18: 0.14 | U18: 0.14 | V18: 0.14 | W18: 0.14 | X18: 0.14 | Y18: 0.14 | Z18: 0.14 | AA18: 0.14 | AB18: 0.14 | AC18: 0.14 | AD18: 0.14 | AE18: 0.14 | AF18: 0.14 | AG18: 0.14 | AH18: 0.14 | AI18: 0.14 | AJ18: 0.14 | AK18: 0.14 | AL18: 0.14 | AM18: 0.14 | AN18: 0.14 | AO18: 0.14 | AP18: 0.14 | AQ18: 0.14 | AR18: 0.14 | AS18: 0.14 | AT18: 0.14 | AU18: 0.14 | AV18: 0.14 | AW18: 0.14 | AX18: 0.14 | AY18: 0.14 | AZ18: 0.14 | BA18: 0.14 | BB18: 0.14 | BC18: 0.14 | BD18: 0.14 | BE18: 0.14 | BF18: 0.14 | BG18: 0.14
A19: eta_en | B19: Shares of Renewable Energy in Total Energy | C19: Z2 | D19: exogenous | F19: 0.14 | G19: 0.14 | H19: 0.14 | I19: 0.14 | J19: 0.14 | K19: 0.14 | L19: 0.14 | M19: 0.14 | N19: 0.14 | O19: 0.14 | P19: 0.14 | Q19: 0.14 | R19: 0.14 | S19: 0.14 | T19: 0.14 | U19: 0.14 | V19: 0.14 | W19: 0.14 | X19: 0.14 | Y19: 0.14 | Z19: 0.14 | AA19: 0.14 | AB19: 0.14 | AC19: 0.14 | AD19: 0.14 | AE19: 0.14 | AF19: 0.14 | AG19: 0.14 | AH19: 0.14 | AI19: 0.14 | AJ19: 0.14 | AK19: 0.14 | AL19: 0.14 | AM19: 0.14 | AN19: 0.14 | AO19: 0.14 | AP19: 0.14 | AQ19: 0.14 | AR19: 0.14 | AS19: 0.14 | AT19: 0.14 | AU19: 0.14 | AV19: 0.14 | AW19: 0.14 | AX19: 0.14 | AY19: 0.14 | AZ19: 0.14 | BA19: 0.14 | BB19: 0.14 | BC19: 0.14 | BD19: 0.14 | BE19: 0.14 | BF19: 0.14 | BG19: 0.14
A20: g_pop | B20: Growth Rate of Native Labour Force | C20: Z1 | D20: exogenous | F20: 0 | G20: 0 | H20: 0 | I20: 0 | J20: 0 | K20: 0 | L20: 0 | M20: 0 | N20: 0 | O20: 0 | P20: 0 | Q20: 0 | R20: 0 | S20: 0 | T20: 0 | U20: 0 | V20: 0 | W20: 0 | X20: 0 | Y20: 0 | Z20: 0 | AA20: 0 | AB20: 0 | AC20: 0 | AD20: 0 | AE20: 0 | AF20: 0 | AG20: 0 | AH20: 0 | AI20: 0 | AJ20: 0 | AK20: 0 | AL20: 0 | AM20: 0 | AN20: 0 | AO20: 0 | AP20: 0 | AQ20: 0 | AR20: 0 | AS20: 0 | AT20: 0 | AU20: 0 | AV20: 0 | AW20: 0 | AX20: 0 | AY20: 0 | AZ20: 0 | BA20: 0 | BB20: 0 | BC20: 0 | BD20: 0 | BE20: 0 | BF20: 0 | BG20: 0
A21: g_pop | B21: Growth Rate of Native Labour Force | C21: Z2 | D21: exogenous | F21: 0 | G21: 0 | H21: 0 | I21: 0 | J21: 0 | K21: 0 | L21: 0 | M21: 0 | N21: 0 | O21: 0 | P21: 0 | Q21: 0 | R21: 0 | S21: 0 | T21: 0 | U21: 0 | V21: 0 | W21: 0 | X21: 0 | Y21: 0 | Z21: 0 | AA21: 0 | AB21: 0 | AC21: 0 | AD21: 0 | AE21: 0 | AF21: 0 | AG21: 0 | AH21: 0 | AI21: 0 | AJ21: 0 | AK21: 0 | AL21: 0 | AM21: 0 | AN21: 0 | AO21: 0 | AP21: 0 | AQ21: 0 | AR21: 0 | AS21: 0 | AT21: 0 | AU21: 0 | AV21: 0 | AW21: 0 | AX21: 0 | AY21: 0 | AZ21: 0 | BA21: 0 | BB21: 0 | BC21: 0 | BD21: 0 | BE21: 0 | BF21: 0 | BG21: 0
A22: gamma_imm_0 | B22: Autonomous Immigration from Z1 to Z2 (by industry) | C22: Z1 | D22: exogenous | F22: 0 | G22: 0 | H22: 0 | I22: 0 | J22: 0 | K22: 0 | L22: 0 | M22: 0 | N22: 0 | O22: 0 | P22: 0 | Q22: 0 | R22: 0 | S22: 0 | T22: 0 | U22: 0 | V22: 0 | W22: 0 | X22: 0 | Y22: 0 | Z22: 0 | AA22: 0 | AB22: 0 | AC22: 0 | AD22: 0 | AE22: 0 | AF22: 0 | AG22: 0 | AH22: 0 | AI22: 0 | AJ22: 0 | AK22: 0 | AL22: 0 | AM22: 0 | AN22: 0 | AO22: 0 | AP22: 0 | AQ22: 0 | AR22: 0 | AS22: 0 | AT22: 0 | AU22: 0 | AV22: 0 | AW22: 0 | AX22: 0 | AY22: 0 | AZ22: 0 | BA22: 0 | BB22: 0 | BC22: 0 | BD22: 0 | BE22: 0 | BF22: 0 | BG22: 0
A23: gamma_imm_0 | B23: Autonomous Immigration from Z2 to Z1 (by industry) | C23: Z2 | D23: exogenous | F23: 0 | G23: 0 | H23: 0 | I23: 0 | J23: 0 | K23: 0 | L23: 0 | M23: 0 | N23: 0 | O23: 0 | P23: 0 | Q23: 0 | R23: 0 | S23: 0 | T23: 0 | U23: 0 | V23: 0 | W23: 0 | X23: 0 | Y23: 0 | Z23: 0 | AA23: 0 | AB23: 0 | AC23: 0 | AD23: 0 | AE23: 0 | AF23: 0 | AG23: 0 | AH23: 0 | AI23: 0 | AJ23: 0 | AK23: 0 | AL23: 0 | AM23: 0 | AN23: 0 | AO23: 0 | AP23: 0 | AQ23: 0 | AR23: 0 | AS23: 0 | AT23: 0 | AU23: 0 | AV23: 0 | AW23: 0 | AX23: 0 | AY23: 0 | AZ23: 0 | BA23: 0 | BB23: 0 | BC23: 0 | BD23: 0 | BE23: 0 | BF23: 0 | BG23: 0
A24: gamma_imm_1 | B24: Immigration from Z1 to Z2 (by industry) Depending on Unemployment Rate | C24: Z1 | D24: exogenous | F24: 0 | G24: 0 | H24: 0 | I24: 0 | J24: 0 | K24: 0 | L24: 0 | M24: 0 | N24: 0 | O24: 0 | P24: 0 | Q24: 0 | R24: 0 | S24: 0 | T24: 0 | U24: 0 | V24: 0 | W24: 0 | X24: 0 | Y24: 0 | Z24: 0 | AA24: 0 | AB24: 0 | AC24: 0 | AD24: 0 | AE24: 0 | AF24: 0 | AG24: 0 | AH24: 0 | AI24: 0 | AJ24: 0 | AK24: 0 | AL24: 0 | AM24: 0 | AN24: 0 | AO24: 0 | AP24: 0 | AQ24: 0 | AR24: 0 | AS24: 0 | AT24: 0 | AU24: 0 | AV24: 0 | AW24: 0 | AX24: 0 | AY24: 0 | AZ24: 0 | BA24: 0 | BB24: 0 | BC24: 0 | BD24: 0 | BE24: 0 | BF24: 0 | BG24: 0
A25: gamma_imm_1 | B25: Immigration from Z2 to Z1 (by industry) Depending on Unemployment Rate | C25: Z2 | D25: exogenous | F25: 0 | G25: 0 | H25: 0 | I25: 0 | J25: 0 | K25: 0 | L25: 0 | M25: 0 | N25: 0 | O25: 0 | P25: 0 | Q25: 0 | R25: 0 | S25: 0 | T25: 0 | U25: 0 | V25: 0 | W25: 0 | X25: 0 | Y25: 0 | Z25: 0 | AA25: 0 | AB25: 0 | AC25: 0 | AD25: 0 | AE25: 0 | AF25: 0 | AG25: 0 | AH25: 0 | AI25: 0 | AJ25: 0 | AK25: 0 | AL25: 0 | AM25: 0 | AN25: 0 | AO25: 0 | AP25: 0 | AQ25: 0 | AR25: 0 | AS25: 0 | AT25: 0 | AU25: 0 | AV25: 0 | AW25: 0 | AX25: 0 | AY25: 0 | AZ25: 0 | BA25: 0 | BB25: 0 | BC25: 0 | BD25: 0 | BE25: 0 | BF25: 0 | BG25: 0
A26: gamma_imm_2 | B26: Immigration from Z1 to Z2 (by industry) Depending on Wage Gap | C26: Z1 | D26: exogenous | F26: 0 | G26: 0 | H26: 0 | I26: 0 | J26: 0 | K26: 0 | L26: 0 | M26: 0 | N26: 0 | O26: 0 | P26: 0 | Q26: 0 | R26: 0 | S26: 0 | T26: 0 | U26: 0 | V26: 0 | W26: 0 | X26: 0 | Y26: 0 | Z26: 0 | AA26: 0 | AB26: 0 | AC26: 0 | AD26: 0 | AE26: 0 | AF26: 0 | AG26: 0 | AH26: 0 | AI26: 0 | AJ26: 0 | AK26: 0 | AL26: 0 | AM26: 0 | AN26: 0 | AO26: 0 | AP26: 0 | AQ26: 0 | AR26: 0 | AS26: 0 | AT26: 0 | AU26: 0 | AV26: 0 | AW26: 0 | AX26: 0 | AY26: 0 | AZ26: 0 | BA26: 0 | BB26: 0 | BC26: 0 | BD26: 0 | BE26: 0 | BF26: 0 | BG26: 0
A27: gamma_imm_2 | B27: Immigration from Z2 to Z1 (by industry) Depending on Wage Gap | C27: Z2 | D27: exogenous | F27: 0 | G27: 0 | H27: 0 | I27: 0 | J27: 0 | K27: 0 | L27: 0 | M27: 0 | N27: 0 | O27: 0 | P27: 0 | Q27: 0 | R27: 0 | S27: 0 | T27: 0 | U27: 0 | V27: 0 | W27: 0 | X27: 0 | Y27: 0 | Z27: 0 | AA27: 0 | AB27: 0 | AC27: 0 | AD27: 0 | AE27: 0 | AF27: 0 | AG27: 0 | AH27: 0 | AI27: 0 | AJ27: 0 | AK27: 0 | AL27: 0 | AM27: 0 | AN27: 0 | AO27: 0 | AP27: 0 | AQ27: 0 | AR27: 0 | AS27: 0 | AT27: 0 | AU27: 0 | AV27: 0 | AW27: 0 | AX27: 0 | AY27: 0 | AZ27: 0 | BA27: 0 | BB27: 0 | BC27: 0 | BD27: 0 | BE27: 0 | BF27: 0 | BG27: 0
... A37: ineq_j | B37: Functional Inequality by Industry | C37: Z2 | D37: endogenous | F37: 0 | G37: 0 | H37: 0 | I37: 0 | J37: 0 | K37: 0 | L37: 0 | M37: 0 | N37: 0 | O37: 0 | P37: 0 | Q37: 0 | R37: 0 | S37: 0 | T37: 0 | U37: 0 | V37: 0 | W37: 0 | X37: 0 | Y37: 0 | Z37: 0 | AA37: 0 | AB37: 0 | AC37: 0 | AD37: 0 | AE37: 0 | AF37: 0 | AG37: 0 | AH37: 0 | AI37: 0 | AJ37: 0 | AK37: 0 | AL37: 0 | AM37: 0 | AN37: 0 | AO37: 0 | AP37: 0 | AQ37: 0 | AR37: 0 | AS37: 0 | AT37: 0 | AU37: 0 | AV37: 0 | AW37: 0 | AX37: 0 | AY37: 0 | AZ37: 0 | BA37: 0 | BB37: 0 | BC37: 0 | BD37: 0 | BE37: 0 | BF37: 0 | BG37: 0
A38: int_j | B38: Interest Payments | C38: Z1 | D38: endogenous | E38: govt.central.bank | F38: 0 | G38: 0 | H38: 0 | I38: 0 | J38: 0 | K38: 0 | L38: 0 | M38: 0 | N38: 0 | O38: 0 | P38: 0 | Q38: 0 | R38: 0 | S38: 0 | T38: 0 | U38: 0 | V38: 0 | W38: 0 | X38: 0 | Y38: 0 | Z38: 0 | AA38: 0 | AB38: 0 | AC38: 0 | AD38: 0 | AE38: 0 | AF38: 0 | AG38: 0 | AH38: 0 | AI38: 0 | AJ38: 0 | AK38: 0 | AL38: 0 | AM38: 0 | AN38: 0 | AO38: 0 | AP38: 0 | AQ38: 0 | AR38: 0 | AS38: 0 | AT38: 0 | AU38: 0 | AV38: 0 | AW38: 0 | AX38: 0 | AY38: 0 | AZ38: 0 | BA38: 0 | BB38: 0 | BC38: 0 | BD38: 0 | BE38: 0 | BF38: 0 | BG38: 0
A39: int_j | B39: Interest Payments | C39: Z2 | D39: endogenous | E39: govt.central.bank | F39: 0 | G39: 0 | H39: 0 | I39: 0 | J39: 0 | K39: 0 | L39: 0 | M39: 0 | N39: 0 | O39: 0 | P39: 0 | Q39: 0 | R39: 0 | S39: 0 | T39: 0 | U39: 0 | V39: 0 | W39: 0 | X39: 0 | Y39: 0 | Z39: 0 | AA39: 0 | AB39: 0 | AC39: 0 | AD39: 0 | AE39: 0 | AF39: 0 | AG39: 0 | AH39: 0 | AI39: 0 | AJ39: 0 | AK39: 0 | AL39: 0 | AM39: 0 | AN39: 0 | AO39: 0 | AP39: 0 | AQ39: 0 | AR39: 0 | AS39: 0 | AT39: 0 | AU39: 0 | AV39: 0 | AW39: 0 | AX39: 0 | AY39: 0 | AZ39: 0 | BA39: 0 | BB39: 0 | BC39: 0 | BD39: 0 | BE39: 0 | BF39: 0 | BG39: 0
A40: iota_Z1 | B40: Z1 Sector Share of Z1 Firm Investment | C40: Z1 | D40: exogenous | F40: 0.0016420411 | G40: 0.0041551413 | H40: 0.0018845891 | I40: 3.892269e-05 | J40: 0.00242247 | K40: 0.0013498272 | L40: 0.0011072806 | M40: 0.0015491581 | N40: 0.00037937362 | O40: 0.001835223 | P40: 0.0035904949 | Q40: 0.0013065301 | R40: 0.0002753431 | S40: 0.00060519328 | T40: 0.0040508387 | U40: 0.0033362055 | V40: 0.0030071313 | W40: 0.0010068888 | X40: 0.00022848318 | Y40: 0.0027557255 | Z40: 0.00021957594 | AA40: 8.0746559e-05 | AB40: 0.00097694253 | AC40: 0.0010055258 | AD40: 0.00022660542 | AE40: 0.0031129185 | AF40: 0.001038252 | AG40: 0.2126446 | AH40: 0.016004153 | AI40: 0.0011834309 | AJ40: 0.0027625626 | AK40: 0.00044599334 | AL40: 0.0037657629 | AM40: 0.0017998142 | AN40: 0.0021200692 | AO40: 0.45929474 | AP40: 0.00055717846 | AQ40: 0.0029583642 | AR40: 0.0012038944 | AS40: 0.024670445 | AT40: 0.0067661148 | AU40: 0.0055471625 | AV40: 0.10460427 | AW40: 0.018972309 | AX40: 0.001991671 | AY40: 0.00056447703 | AZ40: 0.0029972302 | BA40: 0.00025697574 | BB40: 0.00057692931 | BC40: 0.00012313648 | BD40: 7.2048139e-05 | BE40: 4.0876935e-05 | BF40: 0.00010696765 | BG40: 0.00019922368
A41: iota_Z1 | B41: Z2 Sector Share of Z1 Firm Investment | C41: Z2 | D41: exogenous | F41: 0.00064932388 | G41: 0.00014176255 | H41: 4.7272226e-05 | I41: 1.269596e-05 | J41: 0.0085784332 | K41: 0.00053368976 | L41: 0.00013631755 | M41: 0.00014870343 | N41: 9.9485541e-06 | O41: 0.00040331303 | P41: 0.00017804289 | Q41: 7.6593985e-06 | R41: 8.5336937e-05 | S41: 2.6325809e-05 | T41: 0.00022152014 | U41: 0.0015998185 | V41: 0.00023282513 | W41: 2.1450627e-05 | X41: 0.00027482906 | Y41: 0.00037398834 | Z41: 3.6281057e-05 | AA41: 1.7954427e-06 | AB41: 8.5588545e-05 | AC41: 2.0002696e-05 | AD41: 1.3174045e-06 | AE41: 0.00071343181 | AF41: 3.27732e-05 | AG41: 0.056991567 | AH41: 0.0019909417 | AI41: 3.962145e-05 | AJ41: 3.5396758e-05 | AK41: 1.1180679e-05 | AL41: 3.4921156e-05 | AM41: 6.7500998e-06 | AN41: 3.6349299e-05 | AO41: 0.0030242719 | AP41: 5.8754428e-07 | AQ41: 0.00019109264 | AR41: 1.5244728e-05 | AS41: 0.00063424478 | AT41: 0.00019749238 | AU41: 0.00031735013 | AV41: 0.006328988 | AW41: 5.8154194e-05 | AX41: 5.4684395e-06 | AY41: 1.1060404e-05 | AZ41: 3.0965542e-05 | BA41: 8.1417242e-06 | BB41: 1.1193311e-05 | BC41: 6.0424539e-07 | BD41: 6.9905713e-07 | BE41: 3.6501182e-07 | BF41: 9.2740258e-06 | BG41: 1.5808086e-05
A42: iota_Z2 | B42: Z1 Sector Share of Z2 Firm Investment | C42: Z1 | D42: exogenous | F42: 1.8104929e-05 | G42: 5.6350374e-05 | H42: 3.1549326e-06 | I42: 3.4257989e-07 | J42: 7.7247363e-06 | K42: 2.391616e-05 | L42: 1.5799734e-05 | M42: 2.3536972e-05 | N42: 8.9778489e-07 | O42: 9.940234e-05 | P42: 9.098623e-05 | Q42: 2.1876036e-05 | R42: 3.1973381e-06 | S42: 2.765791e-06 | T42: 6.0092346e-05 | U42: 0.0001533413 | V42: 5.5258557e-05 | W42: 1.4977927e-05 | X42: 2.4756757e-05 | Y42: 0.00013718598 | Z42: 6.2645174e-06 | AA42: 2.1904877e-06 | AB42: 1.4159168e-05 | AC42: 1.1982591e-05 | AD42: 2.6168837e-06 | AE42: 0.0001692595 | AF42: 6.6662186e-05 | AG42: 0.028796827 | AH42: 0.00047152593 | AI42: 7.1825783e-06 | AJ42: 2.3283683e-05 | AK42: 3.6115082e-06 | AL42: 2.8737378e-05 | AM42: 8.807656e-06 | AN42: 1.3778818e-05 | AO42: 0.0013460472 | AP42: 2.2790145e-06 | AQ42: 9.2843865e-05 | AR42: 3.1115035e-06 | AS42: 0.00066135817 | AT42: 7.7214952e-05 | AU42: 0.00018996146 | AV42: 0.0023832861 | AW42: 7.7696393e-05 | AX42: 6.8866293e-06 | AY42: 1.9589914e-05 | AZ42: 1.9794846e-05 | BA42: 5.522897e-06 | BB42: 9.3627218e-06 | BC42: 1.3657893e-06 | BD42: 4.3734581e-06 | BE42: 4.7038279e-07 | BF42: 5.5407185e-07 | BG42: 8.0709818e-06
A43: iota_Z2 | B43: Z2 Sector Share of Z2 Firm Investment | C43: Z2 | D43: exogenous | F43: 0.0026820681 | G43: 0.0080925807 | H43: 0.00067100676 | I43: 0.0002693598 | J43: 0.020032197 | K43: 0.0041964351 | L43: 0.0018833542 | M43: 0.00275278 | N43: 0.00011952693 | O43: 0.0032710854 | P43: 0.001668943 | Q43: 4.3578641e-05 | R43: 0.00021638927 | S43: 1.4290971e-05 | T43: 0.0015766548 | U43: 0.0029695645 | V43: 0.00053962449 | W43: 2.5424198e-05 | X43: 0.0022696435 | Y43: 0.0019650859 | Z43: 0.00035179114 | AA43: 2.1976085e-06 | AB43: 0.00061516001 | AC43: 0.00020329906 | AD43: 3.061189e-06 | AE43: 0.005527187 | AF43: 9.912853e-05 | AG43: 0.29979559 | AH43: 0.014215834 | AI43: 0.00024223869 | AJ43: 0.00037616698 | AK43: 9.3657924e-05 | AL43: 0.00082048282 | AM43: 0.00017754448 | AN43: 0.00027288041 | AO43: 0.44722357 | AP43: 2.4431453e-05 | AQ43: 0.0039944178 | AR43: 0.00015160014 | AS43: 0.021631568 | AT43: 0.0023201744 | AU43: 0.0064024701 | AV43: 0.076607406 | AW43: 0.022585158 | AX43: 9.5906297e-05 | AY43: 0.0021625029 | AZ43: 0.0010152623 | BA43: 0.00035390774 | BB43: 0.0011464436 | BC43: 8.4441859e-06 | BD43: 1.3824231e-05 | BE43: 3.0772369e-05 | BF43: 7.7764701e-05 | BG43: 0.00074820599
A44: iota_g_Z1 | B44: Z1 Sector Share of Z1 Public Investment | C44: Z1 | D44: exogenous | F44: 0.0016420411 | G44: 0.0041551413 | H44: 0.0018845891 | I44: 3.892269e-05 | J44: 0.00242247 | K44: 0.0013498272 | L44: 0.0011072806 | M44: 0.0015491581 | N44: 0.00037937362 | O44: 0.001835223 | P44: 0.0035904949 | Q44: 0.0013065301 | R44: 0.0002753431 | S44: 0.00060519328 | T44: 0.0040508387 | U44: 0.0033362055 | V44: 0.0030071313 | W44: 0.0010068888 | X44: 0.00022848318 | Y44: 0.0027557255 | Z44: 0.00021957594 | AA44: 8.0746559e-05 | AB44: 0.00097694253 | AC44: 0.0010055258 | AD44: 0.00022660542 | AE44: 0.0031129185 | AF44: 0.001038252 | AG44: 0.2126446 | AH44: 0.016004153 | AI44: 0.0011834309 | AJ44: 0.0027625626 | AK44: 0.00044599334 | AL44: 0.0037657629 | AM44: 0.0017998142 | AN44: 0.0021200692 | AO44: 0.45929474 | AP44: 0.00055717846 | AQ44: 0.0029583642 | AR44: 0.0012038944 | AS44: 0.024670445 | AT44: 0.0067661148 | AU44: 0.0055471625 | AV44: 0.10460427 | AW44: 0.018972309 | AX44: 0.001991671 | AY44: 0.00056447703 | AZ44: 0.0029972302 | BA44: 0.00025697574 | BB44: 0.00057692931 | BC44: 0.00012313648 | BD44: 7.2048139e-05 | BE44: 4.0876935e-05 | BF44: 0.00010696765 | BG44: 0.00019922368
A45: iota_g_Z1 | B45: Z2 Sector Share of Z1 Public Investment | C45: Z2 | D45: exogenous | F45: 0.00064932388 | G45: 0.00014176255 | H45: 4.7272226e-05 | I45: 1.269596e-05 | J45: 0.0085784332 | K45: 0.00053368976 | L45: 0.00013631755 | M45: 0.00014870343 | N45: 9.9485541e-06 | O45: 0.00040331303 | P45: 0.00017804289 | Q45: 7.6593985e-06 | R45: 8.5336937e-05 | S45: 2.6325809e-05 | T45: 0.00022152014 | U45: 0.0015998185 | V45: 0.00023282513 | W45: 2.1450627e-05 | X45: 0.00027482906 | Y45: 0.00037398834 | Z45: 3.6281057e-05 | AA45: 1.7954427e-06 | AB45: 8.5588545e-05 | AC45: 2.0002696e-05 | AD45: 1.3174045e-06 | AE45: 0.00071343181 | AF45: 3.27732e-05 | AG45: 0.056991567 | AH45: 0.0019909417 | AI45: 3.962145e-05 | AJ45: 3.5396758e-05 | AK45: 1.1180679e-05 | AL45: 3.4921156e-05 | AM45: 6.7500998e-06 | AN45: 3.6349299e-05 | AO45: 0.0030242719 | AP45: 5.8754428e-07 | AQ45: 0.00019109264 | AR45: 1.5244728e-05 | AS45: 0.00063424478 | AT45: 0.00019749238 | AU45: 0.00031735013 | AV45: 0.006328988 | AW45: 5.8154194e-05 | AX45: 5.4684395e-06 | AY45: 1.1060404e-05 | AZ45: 3.0965542e-05 | BA45: 8.1417242e-06 | BB45: 1.1193311e-05 | BC45: 6.0424539e-07 | BD45: 6.9905713e-07 | BE45: 3.6501182e-07 | BF45: 9.2740258e-06 | BG45: 1.5808086e-05
A46: iota_g_Z2 | B46: Z1 Sector Share of Z2 Public Investment | C46: Z1 | D46: exogenous | F46: 1.8104929e-05 | G46: 5.6350374e-05 | H46: 3.1549326e-06 | I46: 3.4257989e-07 | J46: 7.7247363e-06 | K46: 2.391616e-05 | L46: 1.5799734e-05 | M46: 2.3536972e-05 | N46: 8.9778489e-07 | O46: 9.940234e-05 | P46: 9.098623e-05 | Q46: 2.1876036e-05 | R46: 3.1973381e-06 | S46: 2.765791e-06 | T46: 6.0092346e-05 | U46: 0.0001533413 | V46: 5.5258557e-05 | W46: 1.4977927e-05 | X46: 2.4756757e-05 | Y46: 0.00013718598 | Z46: 6.2645174e-06 | AA46: 2.1904877e-06 | AB46: 1.4159168e-05 | AC46: 1.1982591e-05 | AD46: 2.6168837e-06 | AE46: 0.0001692595 | AF46: 6.6662186e-05 | AG46: 0.028796827 | AH46: 0.00047152593 | AI46: 7.1825783e-06 | AJ46: 2.3283683e-05 | AK46: 3.6115082e-06 | AL46: 2.8737378e-05 | AM46: 8.807656e-06 | AN46: 1.3778818e-05 | AO46: 0.0013460472 | AP46: 2.2790145e-06 | AQ46: 9.2843865e-05 | AR46: 3.1115035e-06 | AS46: 0.00066135817 | AT46: 7.7214952e-05 | AU46: 0.00018996146 | AV46: 0.0023832861 | AW46: 7.7696393e-05 | AX46: 6.8866293e-06 | AY46: 1.9589914e-05 | AZ46: 1.9794846e-05 | BA46: 5.522897e-06 | BB46: 9.3627218e-06 | BC46: 1.3657893e-06 | BD46: 4.3734581e-06 | BE46: 4.7038279e-07 | BF46: 5.5407185e-07 | BG46: 8.0709818e-06
A47: iota_g_Z2 | B47: Z2 Sector Share of Z2 Public Investment | C47: Z2 | D47: exogenous | F47: 0.0026820681 | G47: 0.0080925807 | H47: 0.00067100676 | I47: 0.0002693598 | J47: 0.020032197 | K47: 0.0041964351 | L47: 0.0018833542 | M47: 0.00275278 | N47: 0.00011952693 | O47: 0.0032710854 | P47: 0.001668943 | Q47: 4.3578641e-05 | R47: 0.00021638927 | S47: 1.4290971e-05 | T47: 0.0015766548 | U47: 0.0029695645 | V47: 0.00053962449 | W47: 2.5424198e-05 | X47: 0.0022696435 | Y47: 0.0019650859 | Z47: 0.00035179114 | AA47: 2.1976085e-06 | AB47: 0.00061516001 | AC47: 0.00020329906 | AD47: 3.061189e-06 | AE47: 0.005527187 | AF47: 9.912853e-05 | AG47: 0.29979559 | AH47: 0.014215834 | AI47: 0.00024223869 | AJ47: 0.00037616698 | AK47: 9.3657924e-05 | AL47: 0.00082048282 | AM47: 0.00017754448 | AN47: 0.00027288041 | AO47: 0.44722357 | AP47: 2.4431453e-05 | AQ47: 0.0039944178 | AR47: 0.00015160014 | AS47: 0.021631568 | AT47: 0.0023201744 | AU47: 0.0064024701 | AV47: 0.076607406 | AW47: 0.022585158 | AX47: 9.5906297e-05 | AY47: 0.0021625029 | AZ47: 0.0010152623 | BA47: 0.00035390774 | BB47: 0.0011464436 | BC47: 8.4441859e-06 | BD47: 1.3824231e-05 | BE47: 3.0772369e-05 | BF47: 7.7764701e-05 | BG47: 0.00074820599
A48: kappa | B48: Target Fixed Capital to Output Ratio | C48: Z1 | D48: exogenous | E48: investment | F48: 0.325 | G48: 0.325 | H48: 0.325 | I48: 0.325 | J48: 0.325 | K48: 0.325 | L48: 0.325 | M48: 0.325 | N48: 0.325 | O48: 0.325 | P48: 0.325 | Q48: 0.325 | R48: 0.325 | S48: 0.325 | T48: 0.325 | U48: 0.325 | V48: 0.325 | W48: 0.325 | X48: 0.325 | Y48: 0.325 | Z48: 0.325 | AA48: 0.325 | AB48: 0.325 | AC48: 0.325 | AD48: 0.325 | AE48: 0.325 | AF48: 0.325 | AG48: 0.325 | AH48: 0.325 | AI48: 0.325 | AJ48: 0.325 | AK48: 0.325 | AL48: 0.325 | AM48: 0.325 | AN48: 0.325 | AO48: 0.325 | AP48: 0.325 | AQ48: 0.325 | AR48: 0.325 | AS48: 0.325 | AT48: 0.325 | AU48: 0.325 | AV48: 0.325 | AW48: 0.325 | AX48: 0.325 | AY48: 0.325 | AZ48: 0.325 | BA48: 0.325 | BB48: 0.325 | BC48: 0.325 | BD48: 0.325 | BE48: 0.325 | BF48: 0.325 | BG48: 0.325
A49: kappa | B49: Target Fixed Capital to Output Ratio | C49: Z2 | D49: exogenous | E49: investment | F49: 0.33 | G49: 0.33 | H49: 0.33 | I49: 0.33 | J49: 0.33 | K49: 0.33 | L49: 0.33 | M49: 0.33 | N49: 0.33 | O49: 0.33 | P49: 0.33 | Q49: 0.33 | R49: 0.33 | S49: 0.33 | T49: 0.33 | U49: 0.33 | V49: 0.33 | W49: 0.33 | X49: 0.33 | Y49: 0.33 | Z49: 0.33 | AA49: 0.33 | AB49: 0.33 | AC49: 0.33 | AD49: 0.33 | AE49: 0.33 | AF49: 0.33 | AG49: 0.33 | AH49: 0.33 | AI49: 0.33 | AJ49: 0.33 | AK49: 0.33 | AL49: 0.33 | AM49: 0.33 | AN49: 0.33 | AO49: 0.33 | AP49: 0.33 | AQ49: 0.33 | AR49: 0.33 | AS49: 0.33 | AT49: 0.33 | AU49: 0.33 | AV49: 0.33 | AW49: 0.33 | AX49: 0.33 | AY49: 0.33 | AZ49: 0.33 | BA49: 0.33 | BB49: 0.33 | BC49: 0.33 | BD49: 0.33 | BE49: 0.33 | BF49: 0.33 | BG49: 0.33
...

Sheet A.matrix
A1: NA | B1: EU.Agriculture | C1: EU.Animal.Farming | D1: EU.Forestry,.logging.and.related.service.activities.(02) | E1: EU.Fishing,.operating.of.fish.hatcheries.and.fish.farms;.service.activities.incidental.to.fishing.(05) | F1: EU.Extraction.of.Fossil-Fuels | G1: EU.Mining.&.Quarrying.of.raw.materials | H1: EU.Processing.of.meat | I1: EU.Processing.of.other.food&beverage | J1: EU.Manufacture.of.tobacco.products.(16) | K1: EU.Manufacture.of.textiles | L1: EU.Manufacture.of.wood.and.of.products.of.wood.and.cork,.except.furniture;.manufacture.of.articles.of.straw.and.plaiting.materials.(20) | M1: EU.Re-processing.of.secondary.wood.material.into.new.wood.material | N1: EU.Pulp | O1: EU.Re-processing.of.secondary.paper.into.new.pulp | P1: EU.Paper | Q1: EU.Processing.of.Fossil.Fuels | R1: EU.Plastics,.basic | S1: EU.Re-processing.of.secondary.plastic.into.new.plastic | T1: EU.Manufacture.of.Chemicals | U1: EU.Manufacture.of.rubber.and.plastic.products.(25) | V1: EU.Manufacture.of.glass.and.glass.products | W1: EU.Re-processing.of.secondary.glass.into.new.glass | X1: EU.Manufacture.of.other.non-metallic.mineral.products | Y1: EU.Manufacture.of.cement,.lime.and.plaster | Z1: EU.Re-processing.of.ash.into.clinker | AA1: EU.Manufacture.of.Metals | AB1: EU.Re-processing.of.Metals | AC1: EU.Manufacture.of.durable.goods | AD1: EU.Manufacture.of.furniture;.manufacturing.n.e.c..(36) | AE1: EU.Recycling | AF1: EU.Production.of.electricity.by.fossil.fuels | AG1: EU.Production.of.electricity.by.renewable.energy | AH1: EU.Transmission.&.Distribution | AI1: EU.Manufacture.of.gas;.distribution.of.gaseous.fuels.through.mains | AJ1: EU.Water | AK1: EU.Construction.(45) | AL1: EU.Re-processing.of.secondary.construction.material.into.aggregates | AM1: EU.Sale,.maintenance,.repair.of.motor.vehicles,.motor.vehicles.parts,.motorcycles,.motor.cycles.parts.and.accessoiries | AN1: EU.Retail.sale.of.automotive.fuel | AO1: EU.Retail.&.Wholesale.trade | AP1: EU.Leisure.Services | AQ1: EU.Transport | AR1: EU.KIBS | AS1: EU.Real.estate.activities.(70) | AT1: EU.Renting.of.machinery.and.equipment.without.operator.and.of.personal.and.household.goods.(71) | AU1: EU.Research.and.development.(73) | AV1: EU.Public.administration.and.defence;.compulsory.social.security.(75) | AW1: EU.Education.(80) | AX1: EU.Health.and.social.work.(85) | AY1: EU.Incineration.of.Waste | AZ1: EU.Biogas.&.Composting | BA1: EU.Waste.water | BB1: EU.Landfill.of.Waste | BC1: EU.Other.Services | BD1: RoW.Agriculture | BE1: RoW.Animal.Farming | BF1: RoW.Forestry,.logging.and.related.service.activities.(02) | BG1: RoW.Fishing,.operating.of.fish.hatcheries.and.fish.farms;.service.activities.incidental.to.fishing.(05) | BH1: RoW.Extraction.of.Fossil-Fuels | BI1: RoW.Mining.&.Quarrying.of.raw.materials | BJ1: RoW.Processing.of.meat | BK1: RoW.Processing.of.other.food&beverage | BL1: RoW.Manufacture.of.tobacco.products.(16) | BM1: RoW.Manufacture.of.textiles | BN1: RoW.Manufacture.of.wood.and.of.products.of.wood.and.cork,.except.furniture;.manufacture.of.articles.of.straw.and.plaiting.materials.(20) | BO1: RoW.Re-processing.of.secondary.wood.material.into.new.wood.material | BP1: RoW.Pulp | BQ1: RoW.Re-processing.of.secondary.paper.into.new.pulp | BR1: RoW.Paper | BS1: RoW.Processing.of.Fossil.Fuels | BT1: RoW.Plastics,.basic | BU1: RoW.Re-processing.of.secondary.plastic.into.new.plastic | BV1: RoW.Manufacture.of.Chemicals | BW1: RoW.Manufacture.of.rubber.and.plastic.products.(25) | BX1: RoW.Manufacture.of.glass.and.glass.products | BY1: RoW.Re-processing.of.secondary.glass.into.new.glass | BZ1: RoW.Manufacture.of.other.non-metallic.mineral.products | CA1: RoW.Manufacture.of.cement,.lime.and.plaster | CB1: RoW.Re-processing.of.ash.into.clinker | CC1: RoW.Manufacture.of.Metals | CD1: RoW.Re-processing.of.Metals | CE1: RoW.Manufacture.of.durable.goods | CF1: RoW.Manufacture.of.furniture;.manufacturing.n.e.c..(36) | CG1: RoW.Recycling | CH1: RoW.Production.of.electricity.by.fossil.fuels | CI1: RoW.Production.of.electricity.by.renewable.energy | CJ1: RoW.Transmission.&.Distribution | CK1: RoW.Manufacture.of.gas;.distribution.of.gaseous.fuels.through.mains | CL1: RoW.Water | CM1: RoW.Construction.(45) | CN1: RoW.Re-processing.of.secondary.construction.material.into.aggregates | CO1: RoW.Sale,.maintenance,.repair.of.motor.vehicles,.motor.vehicles.parts,.motorcycles,.motor.cycles.parts.and.accessoiries | CP1: RoW.Retail.sale.of.automotive.fuel | CQ1: RoW.Retail.&.Wholesale.trade | CR1: RoW.Leisure.Services | CS1: RoW.Transport | CT1: RoW.KIBS | CU1: RoW.Real.estate.activities.(70) | CV1: RoW.Renting.of.machinery.and.equipment.without.operator.and.of.personal.and.household.goods.(71) | CW1: RoW.Research.and.development.(73) | CX1: RoW.Public.administration.and.defence;.compulsory.social.security.(75) | CY1: RoW.Education.(80) | CZ1: RoW.Health.and.social.work.(85) | DA1: RoW.Incineration.of.Waste | DB1: RoW.Biogas.&.Composting | DC1: RoW.Waste.water | DD1: RoW.Landfill.of.Waste | DE1: RoW.Other.Services
A2: EU.Agriculture | B2: 0.040220156 | C2: 0.099055571 | D2: 0.0088905906 | E2: 0.0017446989 | F2: 0.00021454789 | G2: 0.00033375483 | H2: 0.02990604 | I2: 0.10068127 | J2: 0.027559426 | K2: 0.0020989284 | L2: 0.00042225668 | M2: 0.00053993283 | N2: 0.00043894504 | O2: 0.00039797988 | P2: 0.0002136884 | Q2: 0.00024589338 | R2: 0.0022605377 | S2: 0.0028010487 | T2: 0.0025443375 | U2: 0.00016564498 | V2: 5.5541188e-05 | W2: 6.2681557e-05 | X2: 0.00014919291 | Y2: 7.8002687e-05 | Z2: 8.0086314e-05 | AA2: 7.3510857e-05 | AB2: 0.00010451732 | AC2: 8.751572e-05 | AD2: 0.0001297952 | AE2: 0.00013730428 | AF2: 9.573513e-05 | AG2: 0.0010134057 | AH2: 9.5849738e-05 | AI2: 7.0766266e-05 | AJ2: 0.00018945833 | AK2: 0.00022426122 | AL2: 0.00056012152 | AM2: 4.9125008e-05 | AN2: 0.00030493358 | AO2: 0.0012201294 | AP2: 0.0060530021 | AQ2: 0.00018717819 | AR2: 0.00045925383 | AS2: 7.4341708e-05 | AT2: 0.00035519504 | AU2: 0.00055376749 | AV2: 0.0011089647 | AW2: 0.0004610448 | AX2: 0.0013058866 | AY2: 0.00058796508 | AZ2: 0.00025040786 | BA2: 0.00048730153 | BB2: 0.00043382507 | BC2: 0.00045122728 | BD2: 0.00051400186 | BE2: 0.00072943981 | BF2: 0.00040191954 | BG2: 3.3412405e-05 | BH2: 4.3632105e-05 | BI2: 6.9057266e-05 | BJ2: 0.00025773294 | BK2: 0.0011827594 | BL2: 0.0035040028 | BM2: 0.00032788943 | BN2: 0.00015264439 | BO2: 2.6398217e-05 | BP2: 0.00020885532 | BQ2: 5.1903576e-05 | BR2: 4.3977203e-05 | BS2: 4.3497161e-05 | BT2: 2.442304e-05 | BU2: 9.1334687e-05 | BV2: 0.0010018642 | BW2: 2.4468088e-06 | BX2: 2.0089723e-05 | BY2: 1.3865261e-05 | BZ2: 2.2294429e-05 | CA2: 2.336985e-05 | CB2: 1.3346499e-05 | CC2: 8.6523949e-05 | CD2: 8.8912329e-06 | CE2: 1.1233747e-05 | CF2: 1.8777958e-05 | CG2: 0.00013592084 | CH2: 0.00013474128 | CI2: 0.00015189251 | CJ2: 0.00010877803 | CK2: 0.00050433019 | CL2: 1.5177389e-05 | CM2: 3.6955501e-05 | CN2: 1.1468242e-06 | CO2: 3.3641555e-05 | CP2: 0.00088188592 | CQ2: 3.8427406e-05 | CR2: 0.00022327253 | CS2: 3.0728517e-05 | CT2: 5.0612115e-05 | CU2: 8.6577733e-05 | CV2: 0.00023397863 | CW2: 7.7424732e-05 | CX2: 1.6849608e-05 | CY2: 0.00013234027 | CZ2: 0.00011047333 | DA2: 1.9364969e-06 | DB2: 1.5318832e-06 | DC2: 2.643965e-06 | DD2: 0.00033723313 | DE2: 0.00017756765
A3: EU.Animal Farming | B3: 9.8298293e-05 | C3: 0.0086007575 | D3: 0.00015511801 | E3: 0.00015922693 | F3: 0.00021091683 | G3: 0.00010636645 | H3: 0.22150298 | I3: 0.059257922 | J3: 0.0020070049 | K3: 0.0013633485 | L3: 0.0001261304 | M3: 0.00010370054 | N3: 9.4611581e-05 | O3: 0.00012975777 | P3: 8.4457107e-05 | Q3: 5.2835873e-05 | R3: 0.00013696093 | S3: 0.00021709949 | T3: 0.00012441217 | U3: 5.1670577e-05 | V3: 3.1830989e-05 | W3: 3.525101e-05 | X3: 6.0119279e-05 | Y3: 6.355321e-05 | Z3: 5.56696e-05 | AA3: 6.0030669e-05 | AB3: 4.7682628e-05 | AC3: 7.0084197e-05 | AD3: 7.7613946e-05 | AE3: 6.9496431e-05 | AF3: 0.00010535877 | AG3: 9.2597089e-05 | AH3: 0.00017776581 | AI3: 7.1602852e-05 | AJ3: 5.7073215e-05 | AK3: 6.2860763e-05 | AL3: 0.00073101182 | AM3: 3.4561983e-05 | AN3: 0.0001655975 | AO3: 0.00070264574 | AP3: 0.0013072231 | AQ3: 0.0001208633 | AR3: 0.00016579296 | AS3: 3.2031e-05 | AT3: 0.00030568593 | AU3: 0.00019227326 | AV3: 0.00023201621 | AW3: 0.00011590286 | AX3: 0.0002564465 | AY3: 0.00057810082 | AZ3: 0.00021018164 | BA3: 0.00019912081 | BB3: 0.00012450539 | BC3: 0.0004246123 | BD3: 1.6540377e-05 | BE3: 5.1830957e-05 | BF3: 4.7748956e-06 | BG3: 3.168992e-06 | BH3: 8.1523081e-06 | BI3: 2.2102762e-05 | BJ3: 0.00012074044 | BK3: 6.9213932e-05 | BL3: 2.0140707e-06 | BM3: 5.5766256e-05 | BN3: 4.6700311e-06 | BO3: 2.669822e-05 | BP3: 3.8954956e-06 | BQ3: 1.1992087e-05 | BR3: 2.2273405e-06 | BS3: 0.00013275725 | BT3: 2.9742931e-06 | BU3: 1.4189513e-05 | BV3: 0.00016473343 | BW3: 7.3713659e-06 | BX3: 2.3544306e-06 | BY3: 5.9115356e-06 | BZ3: 1.4568504e-06 | CA3: 1.8955303e-06 | CB3: 5.7837912e-06 | CC3: 4.418151e-05 | CD3: 2.4924024e-06 | CE3: 1.9335085e-06 | CF3: 1.2819866e-05 | CG3: 1.4400424e-05 | CH3: 1.0455059e-06 | CI3: 8.9375167e-06 | CJ3: 5.4096136e-07 | CK3: 2.3341345e-05 | CL3: 7.1281453e-07 | CM3: 2.1965719e-06 | CN3: 1.0712888e-06 | CO3: 2.278121e-06 | CP3: 6.8431547e-06 | CQ3: 3.842944e-06 | CR3: 2.7011694e-05 | CS3: 2.3030468e-06 | CT3: 3.8671963e-06 | CU3: 7.6132743e-06 | CV3: 3.0217672e-05 | CW3: 1.4707473e-05 | CX3: 2.6678292e-06 | CY3: 3.1126531e-05 | CZ3: 1.4184415e-05 | DA3: 2.063203e-06 | DB3: 2.1128044e-06 | DC3: 3.1101022e-06 | DD3: 2.2815613e-06 | DE3: 3.7049851e-05
A4: EU.Forestry, logging and related service activities (02) | B4: 0.00040925073 | C4: 0.0017671034 | D4: 0.21730829 | E4: 0.00030649516 | F4: 0.0009142111 | G4: 0.000766745 | H4: 0.00018376385 | I4: 0.00064722645 | J4: 0.0027556711 | K4: 0.00027100054 | L4: 0.11180325 | M4: 0.0025250698 | N4: 0.044479462 | O4: 0.00025261355 | P4: 0.0066357023 | Q4: 1.8868502e-05 | R4: 0.00017710174 | S4: 0.00022618621 | T4: 0.00035968108 | U4: 0.00039503101 | V4: 0.00028744748 | W4: 0.0001637239 | X4: 0.00024552518 | Y4: 0.00016080363 | Z4: 0.00012627772 | AA4: 7.9739423e-05 | AB4: 6.1039211e-05 | AC4: 5.4821244e-05 | AD4: 0.0025059156 | AE4: 0.00017590149 | AF4: 7.1730759e-05 | AG4: 0.0033805799 | AH4: 6.5401615e-05 | AI4: 2.8406702e-05 | AJ4: 0.00014838132 | AK4: 0.00063586879 | AL4: 1.7073037e-05 | AM4: 3.5563516e-05 | AN4: 5.4764465e-05 | AO4: 0.00011445592 | AP4: 0.0001133158 | AQ4: 4.622908e-05 | AR4: 5.5722516e-05 | AS4: 4.4585482e-05 | AT4: 1.6478819e-05 | AU4: 5.3667903e-05 | AV4: 0.00014506183 | AW4: 3.7306216e-05 | AX4: 2.8009088e-05 | AY4: 6.5038401e-05 | AZ4: 5.0581611e-05 | BA4: 7.6652121e-05 | BB4: 8.3558585e-05 | BC4: 9.8723499e-05 | BD4: 4.6929857e-06 | BE4: 1.4454166e-05 | BF4: 0.00032935255 | BG4: 8.1797621e-07 | BH4: 4.9805543e-06 | BI4: 1.3163564e-06 | BJ4: 9.7801051e-07 | BK4: 1.3659457e-05 | BL4: 6.6143738e-05 | BM4: 1.1932866e-05 | BN4: 0.00087302482 | BO4: 0.00020963987 | BP4: 0.00016469236 | BQ4: 2.513144e-06 | BR4: 0.00011393927 | BS4: 5.5733387e-07 | BT4: 2.6581523e-06 | BU4: 1.1316399e-05 | BV4: 7.0905558e-05 | BW4: 6.4905237e-05 | BX4: 1.5531782e-06 | BY4: 1.0711194e-05 | BZ4: 1.6134963e-06 | CA4: 1.3274952e-06 | CB4: 3.062559e-06 | CC4: 3.7396935e-06 | CD4: 3.7962726e-07 | CE4: 8.530795e-07 | CF4: 4.5248467e-05 | CG4: 1.0309869e-05 | CH4: 1.846343e-07 | CI4: 9.6659257e-07 | CJ4: 2.5606441e-07 | CK4: 1.3960805e-06 | CL4: 3.6051323e-07 | CM4: 1.8494645e-05 | CN4: 1.0030309e-07 | CO4: 5.0529018e-07 | CP4: 3.8328693e-06 | CQ4: 2.1519882e-06 | CR4: 2.7188277e-06 | CS4: 3.9592228e-06 | CT4: 5.6055277e-07 | CU4: 2.0691159e-06 | CV4: 1.9547597e-06 | CW4: 6.3919136e-06 | CX4: 9.6689453e-07 | CY4: 1.608081e-06 | CZ4: 1.5835398e-06 | DA4: 1.5470728e-06 | DB4: 6.6935977e-07 | DC4: 2.8065074e-07 | DD4: 4.3368546e-07 | DE4: 1.2285126e-06
A5: EU.Fishing, operating of fish hatcheries and fish farms; service activities incidental to fishing (05) | B5: 5.4525929e-06 | C5: 0.00038631281 | D5: 0.00038098778 | E5: 0.030494783 | F5: 4.8163126e-06 | G5: 4.9920519e-06 | H5: 0.0021191534 | I5: 0.0022837874 | J5: 0.00090268567 | K5: 7.9124528e-05 | L5: 1.5978572e-05 | M5: 3.8044854e-06 | N5: 1.1703906e-05 | O5: 6.8120673e-06 | P5: 8.4368429e-06 | Q5: 3.1201415e-06 | R5: 0.00020679061 | S5: 0.00022679116 | T5: 4.8317298e-05 | U5: 5.7811307e-05 | V5: 7.8912875e-06 | W5: 9.2011369e-06 | X5: 3.6421669e-06 | Y5: 4.0664143e-06 | Z5: 4.5694837e-06 | AA5: 1.8129009e-06 | AB5: 4.10363e-06 | AC5: 3.1789454e-06 | AD5: 4.3375097e-06 | AE5: 1.8938541e-05 | AF5: 4.1427405e-05 | AG5: 7.8800241e-05 | AH5: 1.9486903e-05 | AI5: 4.604584e-05 | AJ5: 9.1825912e-05 | AK5: 2.7742518e-06 | AL5: 0.045456841 | AM5: 1.5033159e-05 | AN5: 0.00010362751 | AO5: 2.1245963e-05 | AP5: 0.00090976908 | AQ5: 5.0819214e-05 | AR5: 9.6885846e-06 | AS5: 2.2304218e-06 | AT5: 4.9189416e-06 | AU5: 1.5815555e-05 | AV5: 3.5352606e-05 | AW5: 3.0896854e-05 | AX5: 8.139177e-05 | AY5: 2.0345203e-05 | AZ5: 1.0969509e-05 | BA5: 1.6674155e-05 | BB5: 3.6497466e-05 | BC5: 5.1598359e-05 | BD5: 3.2903214e-07 | BE5: 1.486051e-06 | BF5: 2.2131904e-07 | BG5: 0.00022035389 | BH5: 1.6783218e-07 | BI5: 4.7798334e-07 | BJ5: 0.00022032413 | BK5: 3.4741306e-05 | BL5: 3.782609e-07 | BM5: 5.7729517e-07 | BN5: 3.2133405e-07 | BO5: 1.1070917e-06 | BP5: 5.8373597e-07 | BQ5: 1.3859278e-06 | BR5: 1.9400856e-07 | BS5: 8.4506181e-07 | BT5: 5.1822069e-07 | BU5: 9.7431392e-07 | BV5: 2.9107763e-05 | BW5: 1.2403611e-07 | BX5: 1.6968734e-07 | BY5: 4.133814e-07 | BZ5: 2.4358404e-07 | CA5: 2.6170338e-07 | CB5: 4.7148118e-07 | CC5: 1.5187941e-07 | CD5: 2.6804369e-07 | CE5: 2.1070929e-07 | CF5: 2.1703664e-07 | CG5: 9.8458649e-07 | CH5: 1.9352748e-07 | CI5: 2.0873675e-07 | CJ5: 1.297531e-07 | CK5: 3.5681168e-07 | CL5: 1.3314217e-07 | CM5: 3.0648903e-07 | CN5: 9.3487371e-08 | CO5: 1.36053e-07 | CP5: 9.7241229e-06 | CQ5: 6.6357496e-07 | CR5: 1.0008389e-05 | CS5: 2.2153628e-06 | CT5: 3.8888826e-07 | CU5: 1.8888909e-07 | CV5: 3.5320072e-07 | CW5: 9.9952401e-07 | CX5: 8.7205105e-07 | CY5: 1.8403001e-06 | CZ5: 5.4451858e-06 | DA5: 1.8429252e-07 | DB5: 1.2685859e-07 | DC5: 1.2082563e-07 | DD5: 3.3875855e-07 | DE5: 2.7079187e-06
A6: EU.Extraction of Fossil-Fuels | B6: 0.00097568171 | C6: 0.00093357268 | D6: 0.00050609551 | E6: 0.00023870404 | F6: 0.03008272 | G6: 0.0026977009 | H6: 0.00047192112 | I6: 0.00049905769 | J6: 0.00080741828 | K6: 0.0020781898 | L6: 0.0027180802 | M6: 0.0017439113 | N6: 0.0057588138 | O6: 0.0015859841 | P6: 0.00029292384 | Q6: 0.035223138 | R6: 0.002244923 | S6: 0.00062733698 | T6: 0.0059762392 | U6: 0.00053678787 | V6: 0.0021984124 | W6: 0.0049337492 | X6: 0.0028295514 | Y6: 0.0032648901 | Z6: 0.0026450137 | AA6: 0.0071155356 | AB6: 0.0025172566 | AC6: 0.00022537453 | AD6: 0.0016626967 | AE6: 0.00085425024 | AF6: 0.069099996 | AG6: 0.0013648231 | AH6: 0.0012641907 | AI6: 0.016566821 | AJ6: 0.018266864 | AK6: 0.00032028298 | AL6: 7.5453872e-05 | AM6: 0.000142249 | AN6: 0.00083514211 | AO6: 0.00026553114 | AP6: 0.00014561862 | AQ6: 0.00031971073 | AR6: 0.0002095966 | AS6: 0.00017087639 | AT6: 0.00023118383 | AU6: 0.0005229957 | AV6: 0.00046036287 | AW6: 0.00015199904 | AX6: 0.00013228704 | AY6: 0.00034843201 | AZ6: 0.00037145089 | BA6: 0.000508675 | BB6: 0.00040951335 | BC6: 0.00064333639 | BD6: 9.0759379e-06 | BE6: 6.9204814e-06 | BF6: 4.1111287e-06 | BG6: 2.8857369e-06 | BH6: 8.0834715e-05 | BI6: 2.5975086e-05 | BJ6: 8.1644946e-06 | BK6: 7.2940713e-06 | BL6: 4.1234952e-06 | BM6: 1.3753362e-05 | BN6: 0.0018252822 | BO6: 4.4930233e-05 | BP6: 0.00018782762 | BQ6: 2.4884996e-05 | BR6: 6.6228279e-06 | BS6: 0.00098819429 | BT6: 0.00016675945 | BU6: 2.8794208e-05 | BV6: 5.734057e-05 | BW6: 8.0133601e-06 | BX6: 2.2416607e-05 | BY6: 0.00023941206 | BZ6: 3.1888979e-05 | CA6: 9.2816475e-05 | CB6: 0.00027383431 | CC6: 2.5171368e-05 | CD6: 2.5141549e-05 | CE6: 4.6919997e-06 | CF6: 0.00046755682 | CG6: 6.3453343e-06 | CH6: 0.00060118981 | CI6: 4.0665211e-05 | CJ6: 8.788289e-06 | CK6: 0.0013039405 | CL6: 8.8131298e-05 | CM6: 7.6860327e-06 | CN6: 5.3432691e-05 | CO6: 2.387636e-06 | CP6: 1.6380736e-05 | CQ6: 5.5181292e-06 | CR6: 3.8554745e-06 | CS6: 1.0414416e-05 | CT6: 5.2336168e-06 | CU6: 4.3646254e-06 | CV6: 4.9241649e-06 | CW6: 6.2664567e-06 | CX6: 7.7751966e-06 | CY6: 5.6467672e-06 | CZ6: 4.1637073e-06 | DA6: 4.196084e-06 | DB6: 3.4736893e-06 | DC6: 4.9259889e-06 | DD6: 5.0632547e-06 | DE6: 5.2735496e-06
A7: EU.Mining & Quarrying of raw materials | B7: 0.0011436994 | C7: 0.0010978336 | D7: 0.00038518073 | E7: 0.0040482738 | F7: 0.0008150672 | G7: 0.060972898 | H7: 0.00054454051 | I7: 0.0012641715 | J7: 0.00013278964 | K7: 0.00029234715 | L7: 0.00037470608 | M7: 0.00048368945 | N7: 0.0067320476 | O7: 0.0090375812 | P7: 0.0010291693 | Q7: 0.00029460065 | R7: 0.0016233466 | S7: 0.0022736766 | T7: 0.011070902 | U7: 0.0011608932 | V7: 0.047385669 | W7: 0.0027027039 | X7: 0.048487255 | Y7: 0.065427708 | Z7: 0.065193493 | AA7: 0.024580165 | AB7: 0.0032573924 | AC7: 0.00095054333 | AD7: 0.0010549454 | AE7: 0.0016971813 | AF7: 0.00062841672 | AG7: 0.0004462215 | AH7: 0.00065183323 | AI7: 0.0023276407 | AJ7: 0.0012921263 | AK7: 0.0098361662 | AL7: 7.8590124e-05 | AM7: 0.00011977798 | AN7: 0.0010308486 | AO7: 0.00065655285 | AP7: 0.00017645444 | AQ7: 0.0003961277 | AR7: 0.00021015084 | AS7: 0.00018541602 | AT7: 0.00025745729 | AU7: 0.00038975338 | AV7: 0.0010000222 | AW7: 6.6853838e-05 | AX7: 0.00011227529 | AY7: 0.0012624699 | AZ7: 0.0014827991 | BA7: 0.0019704047 | BB7: 0.0019868563 | BC7: 0.00017471437 | BD7: 1.3749989e-05 | BE7: 1.3506838e-05 | BF7: 1.9445013e-05 | BG7: 5.9185976e-05 | BH7: 1.9307998e-05 | BI7: 0.00026921254 | BJ7: 2.288465e-05 | BK7: 1.5647922e-05 | BL7: 1.1810994e-05 | BM7: 2.0096971e-05 | BN7: 1.3522267e-05 | BO7: 1.4042702e-05 | BP7: 6.6108177e-05 | BQ7: 0.00011257911 | BR7: 1.3617222e-05 | BS7: 3.0081618e-05 | BT7: 0.00010459405 | BU7: 0.00025867304 | BV7: 0.00030613862 | BW7: 2.0464972e-05 | BX7: 0.00044883789 | BY7: 5.7196864e-05 | BZ7: 0.00041031779 | CA7: 0.00054666509 | CB7: 0.0012352772 | CC7: 0.00032698016 | CD7: 0.00012194598 | CE7: 3.2960908e-05 | CF7: 0.00014483999 | CG7: 3.4520102e-05 | CH7: 7.4745875e-06 | CI7: 7.5989515e-05 | CJ7: 3.4857823e-06 | CK7: 2.250258e-05 | CL7: 9.9677301e-06 | CM7: 0.00010130187 | CN7: 8.324965e-07 | CO7: 5.2602988e-06 | CP7: 3.3156339e-05 | CQ7: 5.5944545e-06 | CR7: 8.9347133e-06 | CS7: 6.8740113e-06 | CT7: 7.0474271e-06 | CU7: 1.3087142e-05 | CV7: 2.5550006e-05 | CW7: 8.0122776e-06 | CX7: 4.7615549e-06 | CY7: 3.8093921e-05 | CZ7: 2.7086789e-05 | DA7: 7.4654102e-06 | DB7: 5.5051811e-06 | DC7: 7.2664004e-06 | DD7: 1.8170312e-05 | DE7: 1.6449113e-05
